{
 "cells": [
  {
   "cell_type": "code",
   "execution_count": 175,
   "id": "8c24d3da",
   "metadata": {},
   "outputs": [],
   "source": [
    "import numpy as np\n",
    "import pandas as pd\n",
    "import spacy\n",
    "import sklearn as sk"
   ]
  },
  {
   "cell_type": "code",
   "execution_count": 177,
   "id": "7d5e45c5",
   "metadata": {},
   "outputs": [],
   "source": [
    "import meilisearch\n",
    "\n",
    "# CAUTION: PRODUCTION \n",
    "MEILISEARCH_URL = \"http://104.248.158.11\"\n",
    "MEILISEARCH_KEY = \"NDUyZDNiYTM1Njk3ZjM3MzM1MjRiZTVl\"\n",
    "\n",
    "client = meilisearch.Client(MEILISEARCH_URL, MEILISEARCH_KEY)\n",
    "index = client.index(\"articles\")"
   ]
  },
  {
   "cell_type": "code",
   "execution_count": 178,
   "id": "3f1c6524",
   "metadata": {},
   "outputs": [
    {
     "data": {
      "text/plain": [
       "{'taskUid': 9823,\n",
       " 'indexUid': 'articles',\n",
       " 'status': 'enqueued',\n",
       " 'type': 'settingsUpdate',\n",
       " 'enqueuedAt': '2023-01-09T08:16:22.224891952Z'}"
      ]
     },
     "execution_count": 178,
     "metadata": {},
     "output_type": "execute_result"
    }
   ],
   "source": [
    "index.update_ranking_rules([\n",
    "    'words',\n",
    "    'sort',\n",
    "    'typo',\n",
    "    'proximity',\n",
    "    'attribute',\n",
    "    'exactness'\n",
    "])\n",
    "# NOTE: Since `sort` isn't on top, the results are only mostly sorted by publishedTime\n",
    "\n",
    "index.update_displayed_attributes([\n",
    "    \"*\"\n",
    "])\n",
    "# For `search` to return content and embeddings"
   ]
  },
  {
   "cell_type": "code",
   "execution_count": 241,
   "id": "0ecd7d2d",
   "metadata": {},
   "outputs": [],
   "source": [
    "search_term = \"croatia joins euro\"\n",
    "response = index.search(\n",
    "    search_term, \n",
    "    {\n",
    "        \"limit\": 1000,\n",
    "        \"attributesToRetrieve\": [\"uuid\",\"publishedTime\"],\n",
    "        \"sort\": [\"publishedTime:asc\"]\n",
    "    }\n",
    ")\n",
    "result = response[\"hits\"]\n",
    "total_hits = response[\"estimatedTotalHits\"]"
   ]
  },
  {
   "cell_type": "code",
   "execution_count": 242,
   "id": "5cff6167",
   "metadata": {},
   "outputs": [
    {
     "data": {
      "text/plain": [
       "{'hits': [{'uuid': '96fef3dc-793d-4db3-8b52-8bcb305e022c',\n",
       "   'publishedTime': 1672399236},\n",
       "  {'uuid': 'b7f51f57-db39-47e0-b628-905a1d9940aa',\n",
       "   'publishedTime': 1672537112},\n",
       "  {'uuid': '2e582e35-54c5-45c3-8864-e5c29b6bb2d4',\n",
       "   'publishedTime': 1672589074},\n",
       "  {'uuid': '990cddae-a69d-44eb-852a-7fa0cc88b0a5',\n",
       "   'publishedTime': 1672589586},\n",
       "  {'uuid': '086d2d24-e14d-4868-bc7b-bf0c0ff3ded6',\n",
       "   'publishedTime': 1672774729},\n",
       "  {'uuid': '26eaddb0-3264-42c8-a731-0fa925cf3343',\n",
       "   'publishedTime': 1672999215},\n",
       "  {'uuid': 'e505f438-271c-4018-a6b2-28e3cde5c4e8',\n",
       "   'publishedTime': 1671444074},\n",
       "  {'uuid': 'c8da8197-89bd-440b-9056-7bb428400e43',\n",
       "   'publishedTime': 1671472943},\n",
       "  {'uuid': '2fbe5bec-dc83-4cee-ab2f-dfe4cebcf896',\n",
       "   'publishedTime': 1671482800},\n",
       "  {'uuid': '8a84b92c-9686-43c7-a90a-5cf9bbdcd3fc',\n",
       "   'publishedTime': 1671745682},\n",
       "  {'uuid': 'b8e27a07-58f6-4e15-a876-7e0145215176',\n",
       "   'publishedTime': 1671897888},\n",
       "  {'uuid': '263775ad-ade9-49fb-b552-9a68007c1d77',\n",
       "   'publishedTime': 1672223174},\n",
       "  {'uuid': '7ade68f9-d166-4006-8ad6-65dc165c4a0a',\n",
       "   'publishedTime': 1672244926},\n",
       "  {'uuid': '289b5544-8e4d-4dc0-b381-bc207776fdc1',\n",
       "   'publishedTime': 1672245532},\n",
       "  {'uuid': '28e556a6-8887-4c8d-a060-cb2549880e0f',\n",
       "   'publishedTime': 1672258496},\n",
       "  {'uuid': '4ac25fdb-1086-41a3-af6a-8dce72b092cb',\n",
       "   'publishedTime': 1672264973},\n",
       "  {'uuid': 'f9980b15-0596-4cf8-8673-421a13b2474d',\n",
       "   'publishedTime': 1672319628},\n",
       "  {'uuid': '924141ce-e55c-4670-858a-7396ba89c018',\n",
       "   'publishedTime': 1672319652},\n",
       "  {'uuid': 'b877cbfa-c34a-4704-8361-db7c51c5d2d8',\n",
       "   'publishedTime': 1672325856},\n",
       "  {'uuid': '2bd5c2c5-3d73-4d9f-9e53-058389e9ac15',\n",
       "   'publishedTime': 1672378196},\n",
       "  {'uuid': '0c22241a-2b15-4b35-9829-ca631bc1c237',\n",
       "   'publishedTime': 1672390134},\n",
       "  {'uuid': '80b1fa18-987d-41b0-9da1-f51d5dbe87f6',\n",
       "   'publishedTime': 1672407202},\n",
       "  {'uuid': '24def6d6-77f8-40bb-b40b-8adcf1a030fb',\n",
       "   'publishedTime': 1672423283},\n",
       "  {'uuid': 'b97268c6-ecf4-44ec-a74c-9298ed28dc78',\n",
       "   'publishedTime': 1672578868},\n",
       "  {'uuid': 'f20ee9f8-c5ad-4bb6-a91a-6e0eef5fb43e',\n",
       "   'publishedTime': 1672580596},\n",
       "  {'uuid': 'a8286ce1-3aaf-422d-8293-6a7a2e60aa45',\n",
       "   'publishedTime': 1672581620},\n",
       "  {'uuid': '92e3412c-8c25-47a0-a0c2-d5f1dc5d6fcd',\n",
       "   'publishedTime': 1672648337},\n",
       "  {'uuid': '07685c3c-c583-48ea-9cf2-2bb6520d5592',\n",
       "   'publishedTime': 1672754773},\n",
       "  {'uuid': 'cea75dd5-69d2-488a-8ca8-fe14658a10cd',\n",
       "   'publishedTime': 1672900538},\n",
       "  {'uuid': '7b123639-66e4-4be5-90dc-96e6ff1c2673',\n",
       "   'publishedTime': 1672916954},\n",
       "  {'uuid': 'd0a07cda-0d07-49ae-9789-c7fbf820bab9',\n",
       "   'publishedTime': 1672978508},\n",
       "  {'uuid': '1e5915b0-90f3-4312-aa40-067f91764df3',\n",
       "   'publishedTime': 1672999760},\n",
       "  {'uuid': '5122e362-9313-4c5e-a1da-707bc229eaaa',\n",
       "   'publishedTime': 1673000049},\n",
       "  {'uuid': '1599d5e4-4f4d-4ff1-b85a-d92b163893c8',\n",
       "   'publishedTime': 1673028542},\n",
       "  {'uuid': 'cd724cba-8cb4-48b6-9b8d-bd1193f88d4b',\n",
       "   'publishedTime': 1673041298},\n",
       "  {'uuid': 'be48e26b-5d41-46f7-a528-253933cb3ad3',\n",
       "   'publishedTime': 1673041323},\n",
       "  {'uuid': '5fdc7d77-e2be-44f7-a3cd-fb148a850718',\n",
       "   'publishedTime': 1673045424},\n",
       "  {'uuid': 'b82a9958-a1b8-434d-8e97-f568a1d0affe',\n",
       "   'publishedTime': 1673093400},\n",
       "  {'uuid': '40202158-7928-496c-bb38-8d111a407b57',\n",
       "   'publishedTime': 1673093427},\n",
       "  {'uuid': '7e951a69-1052-4d09-8ced-b7a94c002420',\n",
       "   'publishedTime': 1673112833}],\n",
       " 'query': 'croatia joins euro',\n",
       " 'processingTimeMs': 170,\n",
       " 'limit': 1000,\n",
       " 'offset': 0,\n",
       " 'estimatedTotalHits': 40}"
      ]
     },
     "execution_count": 242,
     "metadata": {},
     "output_type": "execute_result"
    }
   ],
   "source": [
    "response"
   ]
  },
  {
   "cell_type": "code",
   "execution_count": 243,
   "id": "127a33f0",
   "metadata": {},
   "outputs": [
    {
     "data": {
      "text/plain": [
       "40"
      ]
     },
     "execution_count": 243,
     "metadata": {},
     "output_type": "execute_result"
    }
   ],
   "source": [
    "total_hits"
   ]
  },
  {
   "cell_type": "code",
   "execution_count": 244,
   "id": "f6ad5db7",
   "metadata": {},
   "outputs": [],
   "source": [
    "# TODO: variable limit and iterate until limit done\n",
    "def get_articles(meilisearch_index, term, sources=None):\n",
    "    response = meilisearch_index.search(\n",
    "        search_term,\n",
    "        {\n",
    "            \"limit\": 1000,\n",
    "            \"attributesToRetrieve\": [\"*\"],\n",
    "            \"sort\": [\"publishedTime:asc\"]\n",
    "        }\n",
    "    )\n",
    "    articles = response[\"hits\"]\n",
    "    return articles\n",
    "    \n"
   ]
  },
  {
   "cell_type": "code",
   "execution_count": 245,
   "id": "b97dc55d",
   "metadata": {
    "scrolled": true
   },
   "outputs": [],
   "source": [
    "articles = get_articles(index, search_term)"
   ]
  },
  {
   "cell_type": "code",
   "execution_count": 246,
   "id": "58dedaca",
   "metadata": {},
   "outputs": [],
   "source": [
    "df = pd.DataFrame.from_records(articles)"
   ]
  },
  {
   "cell_type": "code",
   "execution_count": 247,
   "id": "da24d41d",
   "metadata": {
    "scrolled": false
   },
   "outputs": [],
   "source": [
    "import re\n",
    "\n",
    "def convert_df_column_names_to_camel_case(df):\n",
    "    pattern = re.compile(r'(?<!^)(?=[A-Z])')\n",
    "    new_column_names = [pattern.sub('_', col).lower() for col in df.columns]\n",
    "    old_to_new_name_map = {\n",
    "        col: pattern.sub('_', col).lower()\n",
    "        for col in df.columns\n",
    "    }\n",
    "    return df.rename(columns=old_to_new_name_map)\n",
    "\n",
    "df = convert_df_column_names_to_camel_case(df)"
   ]
  },
  {
   "cell_type": "code",
   "execution_count": 248,
   "id": "bd1eb03f",
   "metadata": {},
   "outputs": [],
   "source": [
    "df.published_time = pd.to_datetime(df.published_time, unit=\"s\")"
   ]
  },
  {
   "cell_type": "code",
   "execution_count": 249,
   "id": "28bdd3ef",
   "metadata": {},
   "outputs": [],
   "source": [
    "from datetime import timedelta\n",
    "\n",
    "def daterange(start_date, end_date, step=timedelta(days=1)):\n",
    "    for n in range(0, int((end_date - start_date).days), step.days):\n",
    "        yield start_date + timedelta(n)\n",
    "\n",
    "def partition_data_into_windows(df, window_delta=0, step=1):\n",
    "    '''\n",
    "    Returns a list of DataFrames, where each DataFrame contains \n",
    "    articles published on some day += window_delta. \n",
    "\n",
    "    Examples: \n",
    "        Parameters           Days contained in each window\n",
    "    window_delta=0, step=1 --> [4-4, 5-5, 6-6, ...]\n",
    "    window_delta=1, step=1 --> [3-5, 4-6, 5-7, ...]\n",
    "    window_delta=2, step=1 --> [2-6, 3-7, 4-8, ...]\n",
    "    window_delta=0, step=2 --> [4-4, 6-6, 8-8, ...]\n",
    "    '''\n",
    "\n",
    "    windows = []\n",
    "\n",
    "    window_size = timedelta(days=window_delta)\n",
    "    start_date = df.published_time.dt.date.min()\n",
    "    end_date = df.published_time.dt.date.max()\n",
    "\n",
    "    for d in daterange(start_date + window_size,\n",
    "                       end_date - window_size + timedelta(days=1), \n",
    "                       timedelta(days=step)):\n",
    "        lower_bound = d - window_size \n",
    "        upper_bound = d + window_size\n",
    "        is_within_window = (lower_bound <= df.published_time.dt.date) & (df.published_time.dt.date <= upper_bound)\n",
    "        data_within_window = df[is_within_window]\n",
    "        windows.append(data_within_window)\n",
    "    \n",
    "    return windows"
   ]
  },
  {
   "cell_type": "code",
   "execution_count": 250,
   "id": "9be31c1b",
   "metadata": {},
   "outputs": [],
   "source": [
    "sliding_windows = partition_data_into_windows(df, 1, 3)"
   ]
  },
  {
   "cell_type": "code",
   "execution_count": 251,
   "id": "06ff47d4",
   "metadata": {},
   "outputs": [],
   "source": [
    "if len(df) < 200:\n",
    "    min_samples = 2\n",
    "else:\n",
    "    min_samples = 3\n",
    "\n",
    "sliding_windows = [window for window in sliding_windows if len(window) >= min_samples]"
   ]
  },
  {
   "cell_type": "markdown",
   "id": "8cc3dd5a",
   "metadata": {},
   "source": [
    "# Visualizing the date distribution"
   ]
  },
  {
   "cell_type": "code",
   "execution_count": 252,
   "id": "37e89fab",
   "metadata": {},
   "outputs": [
    {
     "data": {
      "text/plain": [
       "[(3, Timestamp('2022-12-19 10:01:14')),\n",
       " (2, Timestamp('2022-12-22 21:48:02')),\n",
       " (13, Timestamp('2022-12-30 11:20:36')),\n",
       " (7, Timestamp('2023-01-01 01:38:32')),\n",
       " (4, Timestamp('2023-01-03 19:38:49'))]"
      ]
     },
     "execution_count": 252,
     "metadata": {},
     "output_type": "execute_result"
    },
    {
     "data": {
      "image/png": "iVBORw0KGgoAAAANSUhEUgAAAioAAAGxCAYAAABMeZ2uAAAAOXRFWHRTb2Z0d2FyZQBNYXRwbG90bGliIHZlcnNpb24zLjUuMiwgaHR0cHM6Ly9tYXRwbG90bGliLm9yZy8qNh9FAAAACXBIWXMAAA9hAAAPYQGoP6dpAAAqqUlEQVR4nO3de1RVdcL/8c8R9IgimOIF8nBJU9C0TJvCMqXJW2ZWa2om81LqMzl5jallZI1iF3RWqY2aZVPY85iXmZWmzzxm2UWzx0tKmGhqVhKmFGLK8YJHhe/vj/l5nghQwAP7q7xfa5213Jfz3Z+N7fi49z5nu4wxRgAAABaq43QAAACA8lBUAACAtSgqAADAWhQVAABgLYoKAACwFkUFAABYi6ICAACsRVEBAADWCnY6wMUoLi7WwYMH1ahRI7lcLqfjAACACjDG6NixY4qKilKdOuc/Z3JJF5WDBw/K4/E4HQMAAFTB/v371apVq/Ouc0kXlUaNGkn6946GhYU5nAYAAFSE1+uVx+Px/x4/n0u6qJy73BMWFkZRAQDgElOR2za4mRYAAFiLogIAAKxFUQEAANaiqAAAAGtRVAAAgLUoKgAAwFoUFQAAYC2KCgAAsBZFBQAAWIuiAgAArOVoUTl79qyefvppxcXFKSQkRFdddZWmTp2q4uJiJ2MBAABLOPqsn+nTp+vVV1/VW2+9pQ4dOmjr1q16+OGHFR4ervHjxzsZDQAAWMDRorJx40YNHDhQ/fv3lyTFxsZq8eLF2rp1q5OxAACAJRy99HPLLbfoo48+0tdffy1J+vLLL/XZZ5/pjjvucDIWAACwhKNnVCZOnKiCggLFx8crKChIRUVFev755/XAAw+Uub7P55PP5/NPe73emooKAMBFy8nJUX5+fsDHjYiIUHR0dMDHtYGjRWXp0qVauHChFi1apA4dOmjbtm2aMGGCoqKiNGzYsFLrp6WlKTU11YGkAABcnJycHMXHJ6iw8GTAxw4JaaDdu3ddlmXFZYwxTm3c4/HoySef1OjRo/3znnvuOS1cuFC7d+8utX5ZZ1Q8Ho8KCgoUFhZWI5kBAKiKL774Ql26dNGNwycrLDI2YON6c7O1+c1UZWRk6Prrrw/YuNXJ6/UqPDy8Qr+/HT2jcvLkSdWpU/I2maCgoHI/nux2u+V2u2siGgAA1SIsMlZNots5HeOS4WhRGTBggJ5//nlFR0erQ4cOyszM1IwZMzR8+HAnYwEAAEs4WlRmz56tZ555Ro8++qjy8vIUFRWlRx55RH/5y1+cjAUAACzhaFFp1KiRZs2apVmzZjkZAwAAWIpn/QAAAGtRVAAAgLUoKgAAwFoUFQAAYC2KCgAAsBZFBQAAWIuiAgAArEVRAQAA1qKoAAAAa1FUAACAtSgqAADAWhQVAABgLYoKAACwFkUFAABYi6ICAACsRVEBAADWoqgAAABrUVQAAIC1KCoAAMBaFBUAAGAtigoAALAWRQUAAFiLogIAAKxFUQEAANaiqAAAAGtRVAAAgLUoKgAAwFoUFQAAYC2KCgAAsBZFBQAAWIuiAgAArEVRAQAA1qKoAAAAazlaVGJjY+VyuUq9Ro8e7WQsAABgiWAnN75lyxYVFRX5p3fs2KFevXrpvvvuczAVAACwhaNFpVmzZiWmp02bptatW6tHjx4OJQIAADax5h6V06dPa+HChRo+fLhcLpfTcQAAgAUcPaPyS++++66OHj2qhx56qNx1fD6ffD6ff9rr9dZAMgAA4BRrzqi88cYb6tevn6KiospdJy0tTeHh4f6Xx+OpwYQAAKCmWVFUvv/+e3344YcaOXLkeddLSUlRQUGB/7V///4aSggAAJxgxaWf9PR0NW/eXP379z/vem63W263u4ZSAQAApzl+RqW4uFjp6ekaNmyYgoOt6E0AAMASjheVDz/8UDk5ORo+fLjTUQAAgGUcP4XRu3dvGWOcjgEAACzk+BkVAACA8lBUAACAtSgqAADAWhQVAABgLYoKAACwFkUFAABYi6ICAACsRVEBAADWoqgAAABrUVQAAIC1KCoAAMBaFBUAAGAtigoAALAWRQUAAFiLogIAAKxFUQEAANaiqAAAAGtRVAAAgLUoKgAAwFoUFQAAYC2KCgAAsBZFBQAAWIuiAgAArEVRAQAA1qKoAAAAa1FUAACAtSgqAADAWhQVAABgLYoKAACwFkUFAABYi6ICAACsRVEBAADWoqgAAABrOV5UDhw4oMGDB6tp06Zq0KCBrrvuOmVkZDgdCwAAWCDYyY0fOXJEN998s5KSkvTee++pefPm+vbbb9W4cWMnYwEAAEs4WlSmT58uj8ej9PR0/7zY2FjnAgEAAKs4euln5cqV6tq1q+677z41b95cnTt31uuvv+5kJAAAYBFHz6h89913mjdvnpKTk/XUU0/p888/17hx4+R2uzV06NBS6/t8Pvl8Pv+01+utybgA4KicnBzl5+cHfNyIiAhFR0cHfFwgEBwtKsXFxeratateeOEFSVLnzp21c+dOzZs3r8yikpaWptTU1JqOCQCOy8nJUXx8ggoLTwZ87JCQBtq9exdlBVZytKhERkaqffv2JeYlJCTonXfeKXP9lJQUJScn+6e9Xq88Hk+1ZgQAG+Tn56uw8KRuHD5ZYZGxARvXm5utzW+mKj8/n6ICKzlaVG6++Wbt2bOnxLyvv/5aMTExZa7vdrvldrtrIhoAWCksMlZNots5HQOoMY7eTPvYY49p06ZNeuGFF/TNN99o0aJFmj9/vkaPHu1kLAAAYAlHi8oNN9yg5cuXa/Hixbrmmmv07LPPatasWXrwwQedjAUAACzh6KUfSbrzzjt15513Oh0DAABYyPGv0AcAACgPRQUAAFiLogIAAKxFUQEAANaiqAAAAGtRVAAAgLUoKgAAwFoUFQAAYC2KCgAAsBZFBQAAWIuiAgAArEVRAQAA1qKoAAAAa1FUAACAtSgqAADAWhQVAABgLYoKAACwFkUFAABYi6ICAACsRVEBAADWoqgAAABrUVQAAIC1KCoAAMBaFBUAAGAtigoAALAWRQUAAFiLogIAAKxFUQEAANaiqAAAAGtRVAAAgLUoKgAAwFoUFQAAYC2KCgAAsJajRWXKlClyuVwlXi1btnQyEgAAsEiw0wE6dOigDz/80D8dFBTkYBoAAGATx4tKcHAwZ1EAAECZHL9HZe/evYqKilJcXJz+8Ic/6LvvvnM6EgAAsISjZ1RuvPFG/ed//qfatm2rn376Sc8995y6deumnTt3qmnTpqXW9/l88vl8/mmv11uTcQGUIycnR/n5+QEfNyIiQtHR0QEfV7o0MwO1kaNFpV+/fv4/d+zYUYmJiWrdurXeeustJScnl1o/LS1NqampNRkRwAXk5OQoPj5BhYUnAz52SEgD7d69K+C/+C/FzEBt5fg9Kr/UsGFDdezYUXv37i1zeUpKSokC4/V65fF4aioegDLk5+ersPCkbhw+WWGRsQEb15ubrc1vpio/Pz/gv/QvxcxAbWVVUfH5fNq1a5e6d+9e5nK32y23213DqQBURFhkrJpEt3M6RqVcipmB2sbRm2kff/xxrVu3Tvv27dPmzZv1u9/9Tl6vV8OGDXMyFgAAsISjZ1R++OEHPfDAA8rPz1ezZs100003adOmTYqJiXEyFgAAsISjRWXJkiVObh4AAFjO8e9RAQAAKA9FBQAAWIuiAgAArEVRAQAA1qKoAAAAa1FUAACAtSgqAADAWhQVAABgLYoKAACwFkUFAABYq0pF5aqrrtLhw4dLzT969Kiuuuqqiw4FAAAgVbGoZGdnq6ioqNR8n8+nAwcOXHQoAAAAqZIPJVy5cqX/z++//77Cw8P900VFRfroo48UGxsbsHAAAKB2q1RRufvuuyVJLpdLw4YNK7Gsbt26io2N1UsvvRSwcAAAoHarVFEpLi6WJMXFxWnLli2KiIiollAAAABSJYvKOfv27Qt0DgAAgFKqVFQk6aOPPtJHH32kvLw8/5mWc958882LDgYAAFClopKamqqpU6eqa9euioyMlMvlCnQuAACAqhWVV199VQsWLNCQIUMCnQcAAMCvSt+jcvr0aXXr1i3QWQAAAEqoUlEZOXKkFi1aFOgsAAAAJVTp0s+pU6c0f/58ffjhh+rUqZPq1q1bYvmMGTMCEg4AANRuVSoq27dv13XXXSdJ2rFjR4ll3FgLAAACpUpF5ZNPPgl0DgAAgFKqdI8KAABATajSGZWkpKTzXuL5+OOPqxwIAADgnCoVlXP3p5xz5swZbdu2TTt27Cj1sEIAAICqqlJRmTlzZpnzp0yZouPHj19UIAAAgHMCeo/K4MGDec4PAAAImIAWlY0bN6p+/fqBHBIAANRiVbr0c++995aYNsYoNzdXW7du1TPPPBOQYAAAAFUqKuHh4SWm69Spo3bt2mnq1Knq3bt3QIIBAABUqaikp6cHOgcAAEApF3WPSkZGhhYuXKi3335bmZmZFxUkLS1NLpdLEyZMuKhxAADA5aNKZ1Ty8vL0hz/8QWvXrlXjxo1ljFFBQYGSkpK0ZMkSNWvWrFLjbdmyRfPnz1enTp2qEgcAAFymqnRGZezYsfJ6vdq5c6d+/vlnHTlyRDt27JDX69W4ceMqNdbx48f14IMP6vXXX9cVV1xRlTgAAOAyVaWisnr1as2bN08JCQn+ee3bt9fcuXP13nvvVWqs0aNHq3///rr99turEgUAAFzGqnTpp7i4WHXr1i01v27duiouLq7wOEuWLNEXX3yhLVu2VGh9n88nn8/nn/Z6vRXeFgAAuPRU6YzKbbfdpvHjx+vgwYP+eQcOHNBjjz2m3/72txUaY//+/Ro/frwWLlxY4S+JS0tLU3h4uP/l8XiqEh8AAFwiqlRU5syZo2PHjik2NlatW7dWmzZtFBcXp2PHjmn27NkVGiMjI0N5eXnq0qWLgoODFRwcrHXr1ulvf/ubgoODVVRUVOo9KSkpKigo8L/2799flfgAAOASUaVLPx6PR1988YXWrFmj3bt3yxij9u3bV+o+k9/+9rfKysoqMe/hhx9WfHy8Jk6cqKCgoFLvcbvdcrvdVYkMAAAuQZUqKh9//LHGjBmjTZs2KSwsTL169VKvXr0kSQUFBerQoYNeffVVde/e/YJjNWrUSNdcc02JeQ0bNlTTpk1LzQcAALVTpS79zJo1S//xH/+hsLCwUsvCw8P1yCOPaMaMGQELBwAAardKFZUvv/xSffv2LXd57969lZGRUeUwa9eu1axZs6r8fgAAcHmpVFH56aefyvxY8jnBwcE6dOjQRYcCAACQKllUrrzyylI3wP7S9u3bFRkZedGhAAAApEoWlTvuuEN/+ctfdOrUqVLLCgsLNXnyZN15550BCwcAAGq3Sn3q5+mnn9ayZcvUtm1bjRkzRu3atZPL5dKuXbs0d+5cFRUVadKkSdWVFQAA1DKVKiotWrTQhg0b9Kc//UkpKSkyxkiSXC6X+vTpo1deeUUtWrSolqAAAKD2qfQXvsXExGjVqlU6cuSIvvnmGxljdPXVV/PkYwAAEHBV+mZaSbriiit0ww03BDILAABACVV61g8AAEBNoKgAAABrUVQAAIC1KCoAAMBaFBUAAGAtigoAALAWRQUAAFiLogIAAKxFUQEAANaiqAAAAGtRVAAAgLUoKgAAwFoUFQAAYC2KCgAAsBZFBQAAWIuiAgAArEVRAQAA1qKoAAAAa1FUAACAtSgqAADAWhQVAABgLYoKAACwFkUFAABYi6ICAACsRVEBAADWoqgAAABrOVpU5s2bp06dOiksLExhYWFKTEzUe++952QkAABgEUeLSqtWrTRt2jRt3bpVW7du1W233aaBAwdq586dTsYCAACWCHZy4wMGDCgx/fzzz2vevHnatGmTOnTo4FAqAABgC0eLyi8VFRXpn//8p06cOKHExESn4wAAAAs4XlSysrKUmJioU6dOKTQ0VMuXL1f79u3LXNfn88nn8/mnvV5vtWbLyclRfn5+wMeNiIhQdHR0wMcFLke7du26JMYEnFZd/107/TvL8aLSrl07bdu2TUePHtU777yjYcOGad26dWWWlbS0NKWmptZIrpycHMXHJ6iw8GTAxw4JaaDdu3dRVoDzKCw4LMmlwYMHV9s2zvhOV9vYQE2p7mPF6d9ZjheVevXqqU2bNpKkrl27asuWLXr55Zf12muvlVo3JSVFycnJ/mmv1yuPx1MtufLz81VYeFI3Dp+ssMjYgI3rzc3W5jdTlZ+fT1EBzuPMyWOSjK4bNFHN4uIDOnZu1kbtWDlfZ8+eDei4gBOq81ix4XeW40Xl14wxJS7v/JLb7Zbb7a7RPGGRsWoS3a5Gtwng/4Q2jw74MejNzQ7oeIANquNYsYGjReWpp55Sv3795PF4dOzYMS1ZskRr167V6tWrnYwFAAAs4WhR+emnnzRkyBDl5uYqPDxcnTp10urVq9WrVy8nYwEAAEs4WlTeeOMNJzcPAAAsx7N+AACAtSgqAADAWhQVAABgLYoKAACwFkUFAABYi6ICAACsRVEBAADWoqgAAABrUVQAAIC1KCoAAMBaFBUAAGAtigoAALAWRQUAAFiLogIAAKxFUQEAANaiqAAAAGtRVAAAgLUoKgAAwFoUFQAAYC2KCgAAsBZFBQAAWIuiAgAArEVRAQAA1qKoAAAAa1FUAACAtSgqAADAWhQVAABgLYoKAACwFkUFAABYi6ICAACsRVEBAADWoqgAAABrUVQAAIC1HC0qaWlpuuGGG9SoUSM1b95cd999t/bs2eNkJAAAYBFHi8q6des0evRobdq0SWvWrNHZs2fVu3dvnThxwslYAADAEsFObnz16tUlptPT09W8eXNlZGTo1ltvdSgVAACwhVX3qBQUFEiSmjRp4nASAABgA0fPqPySMUbJycm65ZZbdM0115S5js/nk8/n8097vd6aigcAqIKcnBzl5+cHfNyIiAhFR0cHfFyp+jLv2rUr4GPWBtYUlTFjxmj79u367LPPyl0nLS1NqampNZgKAFBVOTk5io9PUGHhyYCPHRLSQLt37wp4WanOzOec8Z2utrEvR1YUlbFjx2rlypX69NNP1apVq3LXS0lJUXJysn/a6/XK4/HUREQAQCXl5+ersPCkbhw+WWGRsQEb15ubrc1vpio/Pz/gRaW6MktSbtZG7Vg5X2fPng3ouJc7R4uKMUZjx47V8uXLtXbtWsXFxZ13fbfbLbfbXUPpAACBEBYZqybR7ZyOUSnVkdmbmx3Q8WoLR4vK6NGjtWjRIq1YsUKNGjXSjz/+KEkKDw9XSEiIk9EAAIAFHP3Uz7x581RQUKCePXsqMjLS/1q6dKmTsQAAgCUcv/QDAABQHqu+RwUAAOCXKCoAAMBaFBUAAGAtigoAALAWRQUAAFiLogIAAKxFUQEAANaiqAAAAGtRVAAAgLUoKgAAwFoUFQAAYC2KCgAAsBZFBQAAWIuiAgAArEVRAQAA1qKoAAAAa1FUAACAtSgqAADAWhQVAABgLYoKAACwFkUFAABYi6ICAACsRVEBAADWoqgAAABrUVQAAIC1KCoAAMBaFBUAAGAtigoAALAWRQUAAFiLogIAAKxFUQEAANaiqAAAAGtRVAAAgLUcLSqffvqpBgwYoKioKLlcLr377rtOxgEAAJZxtKicOHFC1157rebMmeNkDAAAYKlgJzfer18/9evXz8kIAADAYtyjAgAArOXoGZXK8vl88vl8/mmv1+tgmtolJydH+fn51TJ2RESEoqOjAz7upZgZcMquXbsuiTFR+1xSRSUtLU2pqalOx6h1cnJyFB+foMLCk9UyfkhIA+3evSugv/gvxcyAEwoLDktyafDgwdW2jTO+09U2Ni5/l1RRSUlJUXJysn/a6/XK4/E4mKh2yM/PV2HhSd04fLLCImMDOrY3N1ub30xVfn5+QH/pX4qZASecOXlMktF1gyaqWVx8QMfOzdqoHSvn6+zZswEdF7XLJVVU3G633G630zFqrbDIWDWJbud0jEq5FDMDTghtHh3wY8Wbmx3Q8VA7OVpUjh8/rm+++cY/vW/fPm3btk1NmjThX6oAAMDZorJ161YlJSX5p89d1hk2bJgWLFjgUCoAAGALR4tKz549ZYxxMgIAALAY36MCAACsRVEBAADWoqgAAABrUVQAAIC1KCoAAMBaFBUAAGAtigoAALAWRQUAAFiLogIAAKxFUQEAANaiqAAAAGtRVAAAgLUoKgAAwFoUFQAAYC2KCgAAsBZFBQAAWIuiAgAArEVRAQAA1qKoAAAAa1FUAACAtSgqAADAWhQVAABgLYoKAACwFkUFAABYi6ICAACsRVEBAADWoqgAAABrUVQAAIC1KCoAAMBaFBUAAGAtigoAALAWRQUAAFiLogIAAKzleFF55ZVXFBcXp/r166tLly5av36905EAAIAlHC0qS5cu1YQJEzRp0iRlZmaqe/fu6tevn3JycpyMBQAALOFoUZkxY4ZGjBihkSNHKiEhQbNmzZLH49G8efOcjAUAACzhWFE5ffq0MjIy1Lt37xLze/furQ0bNjiUCgAA2CTYqQ3n5+erqKhILVq0KDG/RYsW+vHHH8t8j8/nk8/n808XFBRIkrxeb8DzHT9+XJL08/d7dNZXGLBxvT/++7JWRkaGfxuBVKdOHRUXFwd0zD179kgK/M9Cqr6fx6WY+Zzq+DusznGr62ftzf1eklRwYK/qBrsCNm51jl2d/23wc/7FuJfgz1mqxp9Hdf4d/v+f9fHjxwP6u/bcWMaYC69sHHLgwAEjyWzYsKHE/Oeee860a9euzPdMnjzZSOLFixcvXrx4XQav/fv3X7AvOHZGJSIiQkFBQaXOnuTl5ZU6y3JOSkqKkpOT/dPFxcX6+eef1bRpU7lcgW2RqF28Xq88Ho/279+vsLAwp+MAtQ7HYO1ijNGxY8cUFRV1wXUdKyr16tVTly5dtGbNGt1zzz3++WvWrNHAgQPLfI/b7Zbb7S4xr3HjxtUZE7VMWFgY/5MEHMQxWHuEh4dXaD3HiookJScna8iQIeratasSExM1f/585eTkaNSoUU7GAgAAlnC0qPz+97/X4cOHNXXqVOXm5uqaa67RqlWrFBMT42QsAABgCUeLiiQ9+uijevTRR52OgVrO7XZr8uTJpS4tAqgZHIMoj8uYinw2CAAAoOY5/qwfAACA8lBUAACAtSgqAADAWhQV1Ji0tDTdcMMNatSokZo3b667777b/3XV5xhjNGXKFEVFRSkkJEQ9e/bUzp07/ct//vlnjR07Vu3atVODBg0UHR2tcePG+R+nIEnZ2dkaMWKE4uLiFBISotatW2vy5Mk6ffr0efOdOnVKDz30kDp27Kjg4GDdfffdpdZZtmyZevXqpWbNmiksLEyJiYl6//33A7Lvv/TII4/I5XJp1qxZFxwbqIyaOg4l6a677lJ0dLTq16+vyMhIDRkyRAcPHrxgxqysLPXo0UMhISG68sorNXXq1BJftZ6bm6tBgwapXbt2qlOnjiZMmFDh/X/llVcUFxen+vXrq0uXLlq/fn2J5VOmTFF8fLwaNmyoK664Qrfffrs2b95c4fEReBQV1Jh169Zp9OjR2rRpk9asWaOzZ8+qd+/eOnHihH+dv/71r5oxY4bmzJmjLVu2qGXLlurVq5eOHTsmSTp48KAOHjyoF198UVlZWVqwYIFWr16tESNG+MfYvXu3iouL9dprr2nnzp2aOXOmXn31VT311FPnzVdUVKSQkBCNGzdOt99+e5nrfPrpp+rVq5dWrVqljIwMJSUlacCAAcrMzLzofT/n3Xff1ebNmyv0jY1AZdXUcShJSUlJ+sc//qE9e/bonXfe0bfffqvf/e53583n9XrVq1cvRUVFacuWLZo9e7ZefPFFzZgxw7+Oz+dTs2bNNGnSJF177bUV3velS5dqwoQJmjRpkjIzM9W9e3f169dPOTk5/nXatm2rOXPmKCsrS5999pliY2PVu3dvHTp0qMLbQYBd5CN7gCrLy8szksy6deuMMcYUFxebli1bmmnTpvnXOXXqlAkPDzevvvpqueP84x//MPXq1TNnzpwpd52//vWvJi4ursLZhg0bZgYOHFihddu3b29SU1MrPLYxpff9nB9++MFceeWVZseOHSYmJsbMnDmzUuMClVWTx+GKFSuMy+Uyp0+fLnedV155xYSHh5tTp07556WlpZmoqChTXFxcav0ePXqY8ePHn28X/X7zm9+YUaNGlZgXHx9vnnzyyXLfU1BQYCSZDz/8sELbQOBxRgWOOXeauEmTJpKkffv26ccff1Tv3r3967jdbvXo0UMbNmw47zhhYWEKDi7/a4EKCgr82wmk4uJiHTt2rNJj/3rfz401ZMgQPfHEE+rQoUNAcwLlqanj8Oeff9bbb7+tbt26qW7duuWOs3HjRvXo0aPE96n06dNHBw8eVHZ2dmV2rYTTp08rIyOjxH5JUu/evcvdr9OnT2v+/PkKDw+v1JkbBBZFBY4wxig5OVm33HKLrrnmGknyP6Dy1w+lbNGiRamHV55z+PBhPfvss3rkkUfK3da3336r2bNnV8ujGV566SWdOHFC999/f4XfU9a+S9L06dMVHByscePGBTwnUJaaOA4nTpyohg0bqmnTpsrJydGKFSvOm+nHH38sc9u/zFYV+fn5KioqqtB+/etf/1JoaKjq16+vmTNnas2aNYqIiKjytnFxKCpwxJgxY7R9+3YtXry41LJfPwnbGFPm07G9Xq/69++v9u3ba/LkyWVu5+DBg+rbt6/uu+8+jRw50j+/Q4cOCg0NVWhoqPr161elfVi8eLGmTJmipUuXqnnz5pKk9evX+8cNDQ3V22+/Xep9Ze17RkaGXn75ZS1YsIAngaPG1MRx+MQTTygzM1MffPCBgoKCNHToUP+NseUdh2Vtu6z55TnfcViR/UpKStK2bdu0YcMG9e3bV/fff7/y8vIqtG0EnuNfoY/aZ+zYsVq5cqU+/fRTtWrVyj+/ZcuWkv79r6bIyEj//Ly8vFL/Cjp27Jj69u2r0NBQLV++vMxTyQcPHlRSUpL/gZe/tGrVKp05c0aSFBISUul9WLp0qUaMGKF//vOfJW687dq1q7Zt2+af/nXu8vZ9/fr1ysvLU3R0tH9eUVGR/vznP2vWrFkXdcobKEtNHYcRERGKiIhQ27ZtlZCQII/Ho02bNikxMbHM47Bly5alznCcKwm/3n55yjoO3W63goKCyhz71+M2bNhQbdq0UZs2bXTTTTfp6quv1htvvKGUlJQKbR+BRVFBjTHGaOzYsVq+fLnWrl2ruLi4Esvj4uLUsmVLrVmzRp07d5b072vE69at0/Tp0/3reb1e9enTR263WytXrlT9+vVLbevAgQNKSkpSly5dlJ6erjp1Sp48vJgHXy5evFjDhw/X4sWL1b9//xLLQkJC1KZNm0rv+5AhQ0p90qhPnz4aMmSIHn744SpnBX6tJo/DsrYt/ftTO1LZx2FiYqKeeuopnT59WvXq1ZMkffDBB4qKilJsbGyF9rG847BLly5as2aN7rnnHv+8NWvWaODAgRfMfS4zHODILbyolf70pz+Z8PBws3btWpObm+t/nTx50r/OtGnTTHh4uFm2bJnJysoyDzzwgImMjDRer9cYY4zX6zU33nij6dixo/nmm29KjHP27FljjDEHDhwwbdq0Mbfddpv54YcfSqxzITt37jSZmZlmwIABpmfPniYzM9NkZmb6ly9atMgEBwebuXPnlhj36NGjF73vv8anflAdauo43Lx5s5k9e7bJzMw02dnZ5uOPPza33HKLad26dYlP9Pza0aNHTYsWLcwDDzxgsrKyzLJly0xYWJh58cUXS6x37tjs0qWLGTRokMnMzDQ7d+48774vWbLE1K1b17zxxhvmq6++MhMmTDANGzY02dnZxhhjjh8/blJSUszGjRtNdna2ycjIMCNGjDBut9vs2LGjSj9vXDyKCmqMpDJf6enp/nWKi4vN5MmTTcuWLY3b7Ta33nqrycrK8i//5JNPyh1n3759xhhj0tPTy13nQmJiYs77vh49epS5fNiwYRe972Vloagg0GrqONy+fbtJSkoyTZo0MW6328TGxppRo0aZH3744YIZt2/fbrp3727cbrdp2bKlmTJlSqmPJpe17ZiYmAuOPXfuXBMTE2Pq1atnrr/++hJfEVBYWGjuueceExUVZerVq2ciIyPNXXfdZT7//PMLjovqw9OTAQCAtfjUDwAAsBZFBQAAWIuiAgAArEVRAQAA1qKoAAAAa1FUAACAtSgqAADAWhQVAABgLYoKAL/s7Gy5XK4SD3T7tbVr18rlcuno0aOSpAULFqhx48YVGr8y61ZGRXJfSM+ePTVhwoSAZQIQGDyUEMBF+f3vf6877rjD6RgVtnbtWiUlJenIkSMlStOyZcvKfPovAGdRVABclJCQEIWEhDgd46I1adLE6QgAysClH+Ay0rNnT40ZM0ZjxoxR48aN1bRpUz399NM690gvl8uld999t8R7GjdurAULFpSYt3v3bnXr1k3169dXhw4dtHbt2nK3+evLOV9++aWSkpLUqFEjhYWFqUuXLtq6dWuJ97z//vtKSEhQaGio+vbtq9zc3BLL09PTlZCQoPr16ys+Pl6vvPJKieWff/65OnfurPr166tr167KzMys0M8nOztbSUlJkqQrrrhCLpdLDz30kKTSl35iY2P13HPPaejQoQoNDVVMTIxWrFihQ4cOaeDAgQoNDVXHjh1L7duGDRt06623KiQkRB6PR+PGjdOJEycqlA9AaRQV4DLz1ltvKTg4WJs3b9bf/vY3zZw5U3//+98rNcYTTzyhP//5z8rMzFS3bt1011136fDhwxV674MPPqhWrVppy5YtysjI0JNPPlniksrJkyf14osv6r/+67/06aefKicnR48//rh/+euvv65Jkybp+eef165du/TCCy/omWee0VtvvSVJOnHihO688061a9dOGRkZmjJlSon3n4/H49E777wjSdqzZ49yc3P18ssvl7v+zJkzdfPNNyszM1P9+/fXkCFDNHToUA0ePFhffPGF2rRpo6FDh/qLYFZWlvr06aN7771X27dv19KlS/XZZ59pzJgxFcoHoAzOPrwZQCD16NHDJCQkmOLiYv+8iRMnmoSEBGOMMZLM8uXLS7wnPDzcpKenG2OM2bdvn5Fkpk2b5l9+5swZ06pVKzN9+nRjjDGffPKJkWSOHDlijDEmPT3dhIeH+9dv1KiRWbBgQZn50tPTjSTzzTff+OfNnTvXtGjRwj/t8XjMokWLSrzv2WefNYmJicYYY1577TXTpEkTc+LECf/yefPmGUkmMzPzPD8dU2b+c3r06GHGjx/vn46JiTGDBw/2T+fm5hpJ5plnnvHP27hxo5FkcnNzjTHGDBkyxPzxj38sMe769etNnTp1TGFh4QWzASiNMyrAZeamm26Sy+XyTycmJmrv3r0qKiqq8BiJiYn+PwcHB6tr167atWtXhd6bnJyskSNH6vbbb9e0adP07bfflljeoEEDtW7d2j8dGRmpvLw8SdKhQ4e0f/9+jRgxQqGhof7Xc8895x9n165duvbaa9WgQYMy8wZSp06d/H9u0aKFJKljx46l5p3Ln5GRoQULFpTI3qdPHxUXF2vfvn3VkhG43HEzLVCLuFwu/2WKc86cOVPh91bElClTNGjQIP3P//yP3nvvPU2ePFlLlizRPffcI0mlPlnzy0zFxcWS/n3558YbbyyxXlBQkCSVyl+dfpn13P6XNe9c7uLiYj3yyCMaN25cqbGio6OrMypw2eKMCnCZ2bRpU6npq6++WkFBQWrWrFmJG1f37t2rkydPnneMs2fPKiMjQ/Hx8RXO0LZtWz322GP64IMPdO+99yo9Pb1C72vRooWuvPJKfffdd2rTpk2JV1xcnCSpffv2+vLLL1VYWFjuPp9PvXr1JKlSZ5gq6vrrr9fOnTtLZW/Tpo1/uwAqh6ICXGb279+v5ORk7dmzR4sXL9bs2bM1fvx4SdJtt92mOXPm6IsvvtDWrVs1atSoMr87ZO7cuVq+fLl2796t0aNH68iRIxo+fPgFt11YWKgxY8Zo7dq1+v777/W///u/2rJlixISEiqcf8qUKUpLS9PLL7+sr7/+WllZWUpPT9eMGTMkSYMGDVKdOnU0YsQIffXVV1q1apVefPHFCo8fExMjl8ulf/3rXzp06JCOHz9e4fdeyMSJE7Vx40aNHj1a27Zt0969e7Vy5UqNHTs2YNsAahuKCnCZGTp0qAoLC/Wb3/xGo0eP1tixY/XHP/5RkvTSSy/J4/Ho1ltv1aBBg/T444+XuNfjnGnTpmn69Om69tprtX79eq1YsUIREREX3HZQUJAOHz6soUOHqm3btrr//vvVr18/paamVjj/yJEj9fe//10LFixQx44d1aNHDy1YsMB/RiU0NFT//d//ra+++kqdO3fWpEmTNH369AqPf+WVVyo1NVVPPvmkWrRoEdBP5HTq1Enr1q3T3r171b17d3Xu3FnPPPOMIiMjA7YNoLZxmZq84AugWvXs2VPXXXedZs2a5XQUAAgIzqgAAABrUVQAXFZGjRpV4uPBv3yNGjXK6XgAKolLPwAuK3l5efJ6vWUuCwsLU/PmzWs4EYCLQVEBAADW4tIPAACwFkUFAABYi6ICAACsRVEBAADWoqgAAABrUVQAAIC1KCoAAMBaFBUAAGCt/weUyK+hAgCKCgAAAABJRU5ErkJggg==\n",
      "text/plain": [
       "<Figure size 640x480 with 1 Axes>"
      ]
     },
     "metadata": {},
     "output_type": "display_data"
    }
   ],
   "source": [
    "import seaborn as sns\n",
    "import matplotlib.ticker as ticker\n",
    "\n",
    "# Plot\n",
    "ax = sns.histplot(df.published_time.dt.date)\n",
    "ax.xaxis.set_major_locator(ticker.MultipleLocator(10))\n",
    "\n",
    "# List\n",
    "[(len(window), window.iloc[0].published_time if len(window) > 0 else \"\") for window in sliding_windows]"
   ]
  },
  {
   "cell_type": "markdown",
   "id": "c7a4b90c",
   "metadata": {},
   "source": [
    "# Clustering"
   ]
  },
  {
   "cell_type": "code",
   "execution_count": 253,
   "id": "386be1cc",
   "metadata": {},
   "outputs": [],
   "source": [
    "from sklearn.cluster import OPTICS\n",
    "\n",
    "def partition_into_clusters(data, fitted_model):\n",
    "    '''\n",
    "    Given a DataFrame and a model fitted on that DataFrame, \n",
    "    returns a list of DataFrames, where each DataFrame contains \n",
    "    data of the same cluster, as labelled by the fitted_model.\n",
    "    '''\n",
    "\n",
    "    labels = np.unique(fitted_model.labels_)\n",
    "    data = [data[fitted_model.labels_ == label] for label in labels]\n",
    "    return data\n",
    "\n",
    "def cluster_each_window(model, sliding_windows, keep_embeddings=False):\n",
    "    '''\n",
    "    Given a model and a list of DataFrames, where sliding_windows[w] is a DataFrame of articles,  \n",
    "    Returns a list of list of DataFrames, where clusters_for_each_window[w][c]\n",
    "    is the DataFrame corresponding to the c-th cluster for the w-th window.\n",
    "    '''\n",
    "\n",
    "    clusters_for_each_window = []\n",
    "    for window in sliding_windows:\n",
    "        x = np.stack(window.embeddings)\n",
    "        model = model.fit(x)\n",
    "        \n",
    "        if not keep_embeddings:\n",
    "            window = window.drop(columns=['embeddings'])\n",
    "\n",
    "        clusters = partition_into_clusters(window, model)\n",
    "        clusters_for_each_window.append(clusters)\n",
    "    return clusters_for_each_window\n",
    "\n",
    "optics = OPTICS(min_samples=min_samples, xi=0.05)\n",
    "clusters_for_each_window = cluster_each_window(optics, sliding_windows, keep_embeddings=True)"
   ]
  },
  {
   "cell_type": "code",
   "execution_count": 254,
   "id": "66df55ae",
   "metadata": {},
   "outputs": [
    {
     "data": {
      "text/plain": [
       "[1, 1, 5, 1, 1]"
      ]
     },
     "execution_count": 254,
     "metadata": {},
     "output_type": "execute_result"
    }
   ],
   "source": [
    "[len(clusters) for clusters in clusters_for_each_window]"
   ]
  },
  {
   "cell_type": "code",
   "execution_count": 255,
   "id": "b47848c2",
   "metadata": {},
   "outputs": [
    {
     "data": {
      "text/plain": [
       "[                                                                              title  \\\n",
       " 16  At Istanbul's Queer Olympix, the aim is for LGBTQ+ athletes to have fun and ...   \n",
       " 18                   Timeline: Case of Charles Sobhraj – ‘Bikini Killer’, ‘Serpent’   \n",
       " \n",
       "                                                                         description  \\\n",
       " 16  The organizers of the annual sports festival in Istanbul see it as an opport...   \n",
       " 18  The French serial killer preyed on Western tourists on the ‘hippie trail’ in...   \n",
       " \n",
       "                                                                             content  \\\n",
       " 16  Every summer since 2017, Istanbul has played host to a sporting event known ...   \n",
       " 18  Charles Sobhraj, a French serial killer who police say is responsible for a ...   \n",
       " \n",
       "                                     uuid  \\\n",
       " 16  bc7f7ee8-34d3-40ad-9dc5-a0c762c30a4d   \n",
       " 18  369c0e97-e281-4977-b970-0590c51d3e96   \n",
       " \n",
       "                                                                       thumbnail_url  \\\n",
       " 16  https://media.npr.org/assets/img/2022/11/23/1_hannah.cauhepe_queer.olympix-1...   \n",
       " 18  https://www.aljazeera.com/wp-content/uploads/2022/12/AP22215714840520-1.jpg?...   \n",
       " \n",
       "                                                                                 url  \\\n",
       " 16  https://www.npr.org/sections/pictureshow/2022/12/22/1138950568/istanbul-quee...   \n",
       " 18  https://www.aljazeera.com/news/2022/12/23/timeline-case-of-charles-sobhraj-b...   \n",
       " \n",
       "         published_time  \\\n",
       " 16 2022-12-22 17:06:13   \n",
       " 18 2022-12-23 09:18:18   \n",
       " \n",
       "                                                                          embeddings  \\\n",
       " 16  [-1.9438403844833376, 1.8494304418563845, -2.4341654777526855, 0.05430549383...   \n",
       " 18  [-2.9253125190734863, 0.797484278678894, -2.1025843620300293, 0.433726310729...   \n",
       " \n",
       "        source  \n",
       " 16        npr  \n",
       " 18  aljazeera  ]"
      ]
     },
     "metadata": {},
     "output_type": "display_data"
    }
   ],
   "source": [
    "def display_series(series):\n",
    "    pd.set_option('display.max_rows', None)\n",
    "    pd.set_option('display.max_colwidth', 80)\n",
    "    display(series)\n",
    "    pd.reset_option('display.max_rows')\n",
    "    pd.reset_option('display.max_colwidth')\n",
    "\n",
    "display_series(clusters)"
   ]
  },
  {
   "cell_type": "code",
   "execution_count": null,
   "id": "4faecf89",
   "metadata": {
    "scrolled": true
   },
   "outputs": [
    {
     "name": "stderr",
     "output_type": "stream",
     "text": [
      "ERROR:root:Internal Python error in the inspect module.\n",
      "Below is the traceback from this internal error.\n",
      "\n",
      "ERROR:root:Internal Python error in the inspect module.\n",
      "Below is the traceback from this internal error.\n",
      "\n",
      "ERROR:root:Internal Python error in the inspect module.\n",
      "Below is the traceback from this internal error.\n",
      "\n"
     ]
    },
    {
     "name": "stdout",
     "output_type": "stream",
     "text": [
      "Traceback (most recent call last):\n",
      "  File \"/Users/cyanaspect/opt/anaconda3/envs/ml/lib/python3.7/site-packages/IPython/core/interactiveshell.py\", line 3457, in run_code\n",
      "    exec(code_obj, self.user_global_ns, self.user_ns)\n",
      "  File \"/var/folders/kg/5sdfljwd58339hwyr4gl3bvh0000gn/T/ipykernel_9521/3680598616.py\", line 1, in <module>\n",
      "    clusters_for_each_window[0][4]\n",
      "IndexError: list index out of range\n",
      "\n",
      "During handling of the above exception, another exception occurred:\n",
      "\n",
      "Traceback (most recent call last):\n",
      "  File \"/Users/cyanaspect/opt/anaconda3/envs/ml/lib/python3.7/site-packages/IPython/core/interactiveshell.py\", line 2077, in showtraceback\n",
      "    stb = value._render_traceback_()\n",
      "AttributeError: 'IndexError' object has no attribute '_render_traceback_'\n",
      "\n",
      "During handling of the above exception, another exception occurred:\n",
      "\n",
      "Traceback (most recent call last):\n",
      "  File \"/Users/cyanaspect/opt/anaconda3/envs/ml/lib/python3.7/site-packages/tensorflow_core/python/pywrap_tensorflow.py\", line 58, in <module>\n",
      "    from tensorflow.python.pywrap_tensorflow_internal import *\n",
      "  File \"/Users/cyanaspect/opt/anaconda3/envs/ml/lib/python3.7/site-packages/tensorflow_core/python/pywrap_tensorflow_internal.py\", line 28, in <module>\n",
      "    _pywrap_tensorflow_internal = swig_import_helper()\n",
      "  File \"/Users/cyanaspect/opt/anaconda3/envs/ml/lib/python3.7/site-packages/tensorflow_core/python/pywrap_tensorflow_internal.py\", line 24, in swig_import_helper\n",
      "    _mod = imp.load_module('_pywrap_tensorflow_internal', fp, pathname, description)\n",
      "  File \"/Users/cyanaspect/opt/anaconda3/envs/ml/lib/python3.7/imp.py\", line 242, in load_module\n",
      "    return load_dynamic(name, filename, file)\n",
      "  File \"/Users/cyanaspect/opt/anaconda3/envs/ml/lib/python3.7/imp.py\", line 342, in load_dynamic\n",
      "    return _load(spec)\n",
      "ImportError: dlopen(/Users/cyanaspect/opt/anaconda3/envs/ml/lib/python3.7/site-packages/tensorflow_core/python/_pywrap_tensorflow_internal.so, 0x0006): Library not loaded: @rpath/libtensorflow_framework.2.dylib\n",
      "  Referenced from: /Users/cyanaspect/opt/anaconda3/envs/ml/lib/python3.7/site-packages/tensorflow_core/python/_pywrap_tensorflow_internal.so\n",
      "  Reason: tried: '/Users/cyanaspect/opt/anaconda3/envs/ml/lib/python3.7/site-packages/tensorflow_core/python/../../_solib_darwin/_U_S_Stensorflow_Spython_C_Upywrap_Utensorflow_Uinternal.so___Utensorflow/libtensorflow_framework.2.dylib' (no such file), '/Users/cyanaspect/opt/anaconda3/envs/ml/lib/python3.7/site-packages/tensorflow_core/python/../../_solib_darwin/_U@mkl_Udarwin_S_S_Cmkl_Ulibs_Udarwin___Uexternal_Smkl_Udarwin_Slib/libtensorflow_framework.2.dylib' (no such file), '/Users/cyanaspect/opt/anaconda3/envs/ml/lib/python3.7/site-packages/tensorflow_core/python/libtensorflow_framework.2.dylib' (no such file), '/Users/cyanaspect/opt/anaconda3/envs/ml/lib/python3.7/site-packages/tensorflow_core/python/../libtensorflow_framework.2.dylib' (no such file), '/Users/cyanaspect/opt/anaconda3/envs/ml/lib/python3.7/site-packages/tensorflow_core/python/../../../../libtensorflow_framework.2.dylib' (no such file), '/Users/cyanaspect/opt/anaconda3/envs/ml/lib/python3.7/site-packages/tensorflow_core/python/../../_solib_darwin/_U_S_Stensorflow_Spython_C_Upywrap_Utensorflow_Uinternal.so___Utensorflow/libtensorflow_framework.2.dylib' (no such file), '/Users/cyanaspect/opt/anaconda3/envs/ml/lib/python3.7/site-packages/tensorflow_core/python/../../_solib_darwin/_U@mkl_Udarwin_S_S_Cmkl_Ulibs_Udarwin___Uexternal_Smkl_Udarwin_Slib/libtensorflow_framework.2.dylib' (no such file), '/Users/cyanaspect/opt/anaconda3/envs/ml/lib/python3.7/site-packages/tensorflow_core/python/libtensorflow_framework.2.dylib' (no such file), '/Users/cyanaspect/opt/anaconda3/envs/ml/lib/python3.7/site-packages/tensorflow_core/python/../libtensorflow_framework.2.dylib' (no such file), '/Users/cyanaspect/opt/anaconda3/envs/ml/lib/python3.7/site-packages/tensorflow_core/python/../../../../libtensorflow_framework.2.dylib' (no such file), '/Users/cyanaspect/opt/anaconda3/envs/ml/bin/../lib/libtensorflow_framework.2.dylib' (no such file), '/Users/cyanaspect/opt/anaconda3/envs/ml/bin/../lib/libtensorflow_framework.2.dylib' (no such file), '/usr/local/lib/libtensorflow_framework.2.dylib' (no such file), '/usr/lib/libtensorflow_framework.2.dylib' (no such file)\n",
      "\n",
      "During handling of the above exception, another exception occurred:\n",
      "\n",
      "Traceback (most recent call last):\n",
      "  File \"/Users/cyanaspect/opt/anaconda3/envs/ml/lib/python3.7/site-packages/IPython/core/ultratb.py\", line 1101, in get_records\n",
      "    return _fixed_getinnerframes(etb, number_of_lines_of_context, tb_offset)\n",
      "  File \"/Users/cyanaspect/opt/anaconda3/envs/ml/lib/python3.7/site-packages/IPython/core/ultratb.py\", line 248, in wrapped\n",
      "    return f(*args, **kwargs)\n",
      "  File \"/Users/cyanaspect/opt/anaconda3/envs/ml/lib/python3.7/site-packages/IPython/core/ultratb.py\", line 281, in _fixed_getinnerframes\n",
      "    records = fix_frame_records_filenames(inspect.getinnerframes(etb, context))\n",
      "  File \"/Users/cyanaspect/opt/anaconda3/envs/ml/lib/python3.7/inspect.py\", line 1502, in getinnerframes\n",
      "    frameinfo = (tb.tb_frame,) + getframeinfo(tb, context)\n",
      "  File \"/Users/cyanaspect/opt/anaconda3/envs/ml/lib/python3.7/inspect.py\", line 1460, in getframeinfo\n",
      "    filename = getsourcefile(frame) or getfile(frame)\n",
      "  File \"/Users/cyanaspect/opt/anaconda3/envs/ml/lib/python3.7/inspect.py\", line 696, in getsourcefile\n",
      "    if getattr(getmodule(object, filename), '__loader__', None) is not None:\n",
      "  File \"/Users/cyanaspect/opt/anaconda3/envs/ml/lib/python3.7/inspect.py\", line 733, in getmodule\n",
      "    if ismodule(module) and hasattr(module, '__file__'):\n",
      "  File \"/Users/cyanaspect/opt/anaconda3/envs/ml/lib/python3.7/site-packages/tensorflow/__init__.py\", line 50, in __getattr__\n",
      "    module = self._load()\n",
      "  File \"/Users/cyanaspect/opt/anaconda3/envs/ml/lib/python3.7/site-packages/tensorflow/__init__.py\", line 44, in _load\n",
      "    module = _importlib.import_module(self.__name__)\n",
      "  File \"/Users/cyanaspect/opt/anaconda3/envs/ml/lib/python3.7/importlib/__init__.py\", line 127, in import_module\n",
      "    return _bootstrap._gcd_import(name[level:], package, level)\n",
      "  File \"<frozen importlib._bootstrap>\", line 1006, in _gcd_import\n",
      "  File \"<frozen importlib._bootstrap>\", line 983, in _find_and_load\n",
      "  File \"<frozen importlib._bootstrap>\", line 953, in _find_and_load_unlocked\n",
      "  File \"<frozen importlib._bootstrap>\", line 219, in _call_with_frames_removed\n",
      "  File \"<frozen importlib._bootstrap>\", line 1006, in _gcd_import\n",
      "  File \"<frozen importlib._bootstrap>\", line 983, in _find_and_load\n",
      "  File \"<frozen importlib._bootstrap>\", line 967, in _find_and_load_unlocked\n",
      "  File \"<frozen importlib._bootstrap>\", line 677, in _load_unlocked\n",
      "  File \"<frozen importlib._bootstrap_external>\", line 728, in exec_module\n",
      "  File \"<frozen importlib._bootstrap>\", line 219, in _call_with_frames_removed\n",
      "  File \"/Users/cyanaspect/opt/anaconda3/envs/ml/lib/python3.7/site-packages/tensorflow_core/__init__.py\", line 42, in <module>\n",
      "    from . _api.v2 import audio\n",
      "  File \"/Users/cyanaspect/opt/anaconda3/envs/ml/lib/python3.7/site-packages/tensorflow_core/_api/v2/audio/__init__.py\", line 10, in <module>\n",
      "    from tensorflow.python.ops.gen_audio_ops import decode_wav\n",
      "  File \"/Users/cyanaspect/opt/anaconda3/envs/ml/lib/python3.7/site-packages/tensorflow_core/python/ops/gen_audio_ops.py\", line 10, in <module>\n",
      "    from tensorflow.python import pywrap_tensorflow as _pywrap_tensorflow\n",
      "  File \"/Users/cyanaspect/opt/anaconda3/envs/ml/lib/python3.7/site-packages/tensorflow/__init__.py\", line 50, in __getattr__\n",
      "    module = self._load()\n",
      "  File \"/Users/cyanaspect/opt/anaconda3/envs/ml/lib/python3.7/site-packages/tensorflow/__init__.py\", line 44, in _load\n",
      "    module = _importlib.import_module(self.__name__)\n",
      "  File \"/Users/cyanaspect/opt/anaconda3/envs/ml/lib/python3.7/importlib/__init__.py\", line 127, in import_module\n",
      "    return _bootstrap._gcd_import(name[level:], package, level)\n",
      "  File \"/Users/cyanaspect/opt/anaconda3/envs/ml/lib/python3.7/site-packages/tensorflow_core/python/__init__.py\", line 49, in <module>\n",
      "    from tensorflow.python import pywrap_tensorflow\n",
      "  File \"/Users/cyanaspect/opt/anaconda3/envs/ml/lib/python3.7/site-packages/tensorflow_core/python/pywrap_tensorflow.py\", line 74, in <module>\n",
      "    raise ImportError(msg)\n",
      "ImportError: Traceback (most recent call last):\n",
      "  File \"/Users/cyanaspect/opt/anaconda3/envs/ml/lib/python3.7/site-packages/IPython/core/interactiveshell.py\", line 3457, in run_code\n",
      "    exec(code_obj, self.user_global_ns, self.user_ns)\n",
      "  File \"/var/folders/kg/5sdfljwd58339hwyr4gl3bvh0000gn/T/ipykernel_9521/3680598616.py\", line 1, in <module>\n",
      "    clusters_for_each_window[0][4]\n",
      "IndexError: list index out of range\n",
      "\n",
      "During handling of the above exception, another exception occurred:\n",
      "\n",
      "Traceback (most recent call last):\n",
      "  File \"/Users/cyanaspect/opt/anaconda3/envs/ml/lib/python3.7/site-packages/IPython/core/interactiveshell.py\", line 2077, in showtraceback\n",
      "    stb = value._render_traceback_()\n",
      "AttributeError: 'IndexError' object has no attribute '_render_traceback_'\n",
      "\n",
      "During handling of the above exception, another exception occurred:\n",
      "\n",
      "Traceback (most recent call last):\n",
      "  File \"/Users/cyanaspect/opt/anaconda3/envs/ml/lib/python3.7/site-packages/tensorflow_core/python/pywrap_tensorflow.py\", line 58, in <module>\n",
      "    from tensorflow.python.pywrap_tensorflow_internal import *\n",
      "  File \"/Users/cyanaspect/opt/anaconda3/envs/ml/lib/python3.7/site-packages/tensorflow_core/python/pywrap_tensorflow_internal.py\", line 28, in <module>\n",
      "    _pywrap_tensorflow_internal = swig_import_helper()\n",
      "  File \"/Users/cyanaspect/opt/anaconda3/envs/ml/lib/python3.7/site-packages/tensorflow_core/python/pywrap_tensorflow_internal.py\", line 24, in swig_import_helper\n",
      "    _mod = imp.load_module('_pywrap_tensorflow_internal', fp, pathname, description)\n",
      "  File \"/Users/cyanaspect/opt/anaconda3/envs/ml/lib/python3.7/imp.py\", line 242, in load_module\n",
      "    return load_dynamic(name, filename, file)\n",
      "  File \"/Users/cyanaspect/opt/anaconda3/envs/ml/lib/python3.7/imp.py\", line 342, in load_dynamic\n",
      "    return _load(spec)\n",
      "ImportError: dlopen(/Users/cyanaspect/opt/anaconda3/envs/ml/lib/python3.7/site-packages/tensorflow_core/python/_pywrap_tensorflow_internal.so, 0x0006): Library not loaded: @rpath/libtensorflow_framework.2.dylib\n",
      "  Referenced from: /Users/cyanaspect/opt/anaconda3/envs/ml/lib/python3.7/site-packages/tensorflow_core/python/_pywrap_tensorflow_internal.so\n",
      "  Reason: tried: '/Users/cyanaspect/opt/anaconda3/envs/ml/lib/python3.7/site-packages/tensorflow_core/python/../../_solib_darwin/_U_S_Stensorflow_Spython_C_Upywrap_Utensorflow_Uinternal.so___Utensorflow/libtensorflow_framework.2.dylib' (no such file), '/Users/cyanaspect/opt/anaconda3/envs/ml/lib/python3.7/site-packages/tensorflow_core/python/../../_solib_darwin/_U@mkl_Udarwin_S_S_Cmkl_Ulibs_Udarwin___Uexternal_Smkl_Udarwin_Slib/libtensorflow_framework.2.dylib' (no such file), '/Users/cyanaspect/opt/anaconda3/envs/ml/lib/python3.7/site-packages/tensorflow_core/python/libtensorflow_framework.2.dylib' (no such file), '/Users/cyanaspect/opt/anaconda3/envs/ml/lib/python3.7/site-packages/tensorflow_core/python/../libtensorflow_framework.2.dylib' (no such file), '/Users/cyanaspect/opt/anaconda3/envs/ml/lib/python3.7/site-packages/tensorflow_core/python/../../../../libtensorflow_framework.2.dylib' (no such file), '/Users/cyanaspect/opt/anaconda3/envs/ml/lib/python3.7/site-packages/tensorflow_core/python/../../_solib_darwin/_U_S_Stensorflow_Spython_C_Upywrap_Utensorflow_Uinternal.so___Utensorflow/libtensorflow_framework.2.dylib' (no such file), '/Users/cyanaspect/opt/anaconda3/envs/ml/lib/python3.7/site-packages/tensorflow_core/python/../../_solib_darwin/_U@mkl_Udarwin_S_S_Cmkl_Ulibs_Udarwin___Uexternal_Smkl_Udarwin_Slib/libtensorflow_framework.2.dylib' (no such file), '/Users/cyanaspect/opt/anaconda3/envs/ml/lib/python3.7/site-packages/tensorflow_core/python/libtensorflow_framework.2.dylib' (no such file), '/Users/cyanaspect/opt/anaconda3/envs/ml/lib/python3.7/site-packages/tensorflow_core/python/../libtensorflow_framework.2.dylib' (no such file), '/Users/cyanaspect/opt/anaconda3/envs/ml/lib/python3.7/site-packages/tensorflow_core/python/../../../../libtensorflow_framework.2.dylib' (no such file), '/Users/cyanaspect/opt/anaconda3/envs/ml/bin/../lib/libtensorflow_framework.2.dylib' (no such file), '/Users/cyanaspect/opt/anaconda3/envs/ml/bin/../lib/libtensorflow_framework.2.dylib' (no such file), '/usr/local/lib/libtensorflow_framework.2.dylib' (no such file), '/usr/lib/libtensorflow_framework.2.dylib' (no such file)\n",
      "\n",
      "\n",
      "Failed to load the native TensorFlow runtime.\n",
      "\n",
      "See https://www.tensorflow.org/install/errors\n",
      "\n",
      "for some common reasons and solutions.  Include the entire stack trace\n",
      "above this error message when asking for help.\n",
      "Traceback (most recent call last):\n",
      "  File \"/Users/cyanaspect/opt/anaconda3/envs/ml/lib/python3.7/site-packages/IPython/core/interactiveshell.py\", line 3457, in run_code\n",
      "    exec(code_obj, self.user_global_ns, self.user_ns)\n",
      "  File \"/var/folders/kg/5sdfljwd58339hwyr4gl3bvh0000gn/T/ipykernel_9521/3680598616.py\", line 1, in <module>\n",
      "    clusters_for_each_window[0][4]\n",
      "IndexError: list index out of range\n",
      "\n",
      "During handling of the above exception, another exception occurred:\n",
      "\n",
      "Traceback (most recent call last):\n",
      "  File \"/Users/cyanaspect/opt/anaconda3/envs/ml/lib/python3.7/site-packages/IPython/core/interactiveshell.py\", line 2077, in showtraceback\n",
      "    stb = value._render_traceback_()\n",
      "AttributeError: 'IndexError' object has no attribute '_render_traceback_'\n",
      "\n",
      "During handling of the above exception, another exception occurred:\n",
      "\n",
      "Traceback (most recent call last):\n",
      "  File \"/Users/cyanaspect/opt/anaconda3/envs/ml/lib/python3.7/site-packages/IPython/core/interactiveshell.py\", line 3377, in run_ast_nodes\n",
      "    if (await self.run_code(code, result,  async_=asy)):\n",
      "  File \"/Users/cyanaspect/opt/anaconda3/envs/ml/lib/python3.7/site-packages/IPython/core/interactiveshell.py\", line 3474, in run_code\n",
      "    self.showtraceback(running_compiled_code=True)\n",
      "  File \"/Users/cyanaspect/opt/anaconda3/envs/ml/lib/python3.7/site-packages/IPython/core/interactiveshell.py\", line 2080, in showtraceback\n",
      "    value, tb, tb_offset=tb_offset)\n",
      "  File \"/Users/cyanaspect/opt/anaconda3/envs/ml/lib/python3.7/site-packages/IPython/core/ultratb.py\", line 1368, in structured_traceback\n",
      "    self, etype, value, tb, tb_offset, number_of_lines_of_context)\n",
      "  File \"/Users/cyanaspect/opt/anaconda3/envs/ml/lib/python3.7/site-packages/IPython/core/ultratb.py\", line 1268, in structured_traceback\n",
      "    self, etype, value, tb, tb_offset, number_of_lines_of_context\n",
      "  File \"/Users/cyanaspect/opt/anaconda3/envs/ml/lib/python3.7/site-packages/IPython/core/ultratb.py\", line 1125, in structured_traceback\n",
      "    tb_offset)\n",
      "  File \"/Users/cyanaspect/opt/anaconda3/envs/ml/lib/python3.7/site-packages/IPython/core/ultratb.py\", line 1082, in format_exception_as_a_whole\n",
      "    last_unique, recursion_repeat = find_recursion(orig_etype, evalue, records)\n",
      "  File \"/Users/cyanaspect/opt/anaconda3/envs/ml/lib/python3.7/site-packages/IPython/core/ultratb.py\", line 382, in find_recursion\n",
      "    return len(records), 0\n",
      "TypeError: object of type 'NoneType' has no len()\n",
      "\n",
      "During handling of the above exception, another exception occurred:\n",
      "\n",
      "Traceback (most recent call last):\n",
      "  File \"/Users/cyanaspect/opt/anaconda3/envs/ml/lib/python3.7/site-packages/IPython/core/interactiveshell.py\", line 2077, in showtraceback\n",
      "    stb = value._render_traceback_()\n",
      "AttributeError: 'TypeError' object has no attribute '_render_traceback_'\n",
      "\n",
      "During handling of the above exception, another exception occurred:\n",
      "\n",
      "Traceback (most recent call last):\n",
      "  File \"/Users/cyanaspect/opt/anaconda3/envs/ml/lib/python3.7/site-packages/tensorflow_core/python/pywrap_tensorflow.py\", line 58, in <module>\n",
      "    from tensorflow.python.pywrap_tensorflow_internal import *\n",
      "  File \"/Users/cyanaspect/opt/anaconda3/envs/ml/lib/python3.7/site-packages/tensorflow_core/python/pywrap_tensorflow_internal.py\", line 28, in <module>\n",
      "    _pywrap_tensorflow_internal = swig_import_helper()\n",
      "  File \"/Users/cyanaspect/opt/anaconda3/envs/ml/lib/python3.7/site-packages/tensorflow_core/python/pywrap_tensorflow_internal.py\", line 24, in swig_import_helper\n",
      "    _mod = imp.load_module('_pywrap_tensorflow_internal', fp, pathname, description)\n",
      "  File \"/Users/cyanaspect/opt/anaconda3/envs/ml/lib/python3.7/imp.py\", line 242, in load_module\n",
      "    return load_dynamic(name, filename, file)\n",
      "  File \"/Users/cyanaspect/opt/anaconda3/envs/ml/lib/python3.7/imp.py\", line 342, in load_dynamic\n",
      "    return _load(spec)\n",
      "ImportError: dlopen(/Users/cyanaspect/opt/anaconda3/envs/ml/lib/python3.7/site-packages/tensorflow_core/python/_pywrap_tensorflow_internal.so, 0x0006): Library not loaded: @rpath/libtensorflow_framework.2.dylib\n",
      "  Referenced from: /Users/cyanaspect/opt/anaconda3/envs/ml/lib/python3.7/site-packages/tensorflow_core/python/_pywrap_tensorflow_internal.so\n",
      "  Reason: tried: '/Users/cyanaspect/opt/anaconda3/envs/ml/lib/python3.7/site-packages/tensorflow_core/python/../../_solib_darwin/_U_S_Stensorflow_Spython_C_Upywrap_Utensorflow_Uinternal.so___Utensorflow/libtensorflow_framework.2.dylib' (no such file), '/Users/cyanaspect/opt/anaconda3/envs/ml/lib/python3.7/site-packages/tensorflow_core/python/../../_solib_darwin/_U@mkl_Udarwin_S_S_Cmkl_Ulibs_Udarwin___Uexternal_Smkl_Udarwin_Slib/libtensorflow_framework.2.dylib' (no such file), '/Users/cyanaspect/opt/anaconda3/envs/ml/lib/python3.7/site-packages/tensorflow_core/python/libtensorflow_framework.2.dylib' (no such file), '/Users/cyanaspect/opt/anaconda3/envs/ml/lib/python3.7/site-packages/tensorflow_core/python/../libtensorflow_framework.2.dylib' (no such file), '/Users/cyanaspect/opt/anaconda3/envs/ml/lib/python3.7/site-packages/tensorflow_core/python/../../../../libtensorflow_framework.2.dylib' (no such file), '/Users/cyanaspect/opt/anaconda3/envs/ml/lib/python3.7/site-packages/tensorflow_core/python/../../_solib_darwin/_U_S_Stensorflow_Spython_C_Upywrap_Utensorflow_Uinternal.so___Utensorflow/libtensorflow_framework.2.dylib' (no such file), '/Users/cyanaspect/opt/anaconda3/envs/ml/lib/python3.7/site-packages/tensorflow_core/python/../../_solib_darwin/_U@mkl_Udarwin_S_S_Cmkl_Ulibs_Udarwin___Uexternal_Smkl_Udarwin_Slib/libtensorflow_framework.2.dylib' (no such file), '/Users/cyanaspect/opt/anaconda3/envs/ml/lib/python3.7/site-packages/tensorflow_core/python/libtensorflow_framework.2.dylib' (no such file), '/Users/cyanaspect/opt/anaconda3/envs/ml/lib/python3.7/site-packages/tensorflow_core/python/../libtensorflow_framework.2.dylib' (no such file), '/Users/cyanaspect/opt/anaconda3/envs/ml/lib/python3.7/site-packages/tensorflow_core/python/../../../../libtensorflow_framework.2.dylib' (no such file), '/Users/cyanaspect/opt/anaconda3/envs/ml/bin/../lib/libtensorflow_framework.2.dylib' (no such file), '/Users/cyanaspect/opt/anaconda3/envs/ml/bin/../lib/libtensorflow_framework.2.dylib' (no such file), '/usr/local/lib/libtensorflow_framework.2.dylib' (no such file), '/usr/lib/libtensorflow_framework.2.dylib' (no such file)\n",
      "\n",
      "During handling of the above exception, another exception occurred:\n",
      "\n",
      "Traceback (most recent call last):\n",
      "  File \"/Users/cyanaspect/opt/anaconda3/envs/ml/lib/python3.7/site-packages/IPython/core/ultratb.py\", line 1101, in get_records\n",
      "    return _fixed_getinnerframes(etb, number_of_lines_of_context, tb_offset)\n",
      "  File \"/Users/cyanaspect/opt/anaconda3/envs/ml/lib/python3.7/site-packages/IPython/core/ultratb.py\", line 248, in wrapped\n",
      "    return f(*args, **kwargs)\n",
      "  File \"/Users/cyanaspect/opt/anaconda3/envs/ml/lib/python3.7/site-packages/IPython/core/ultratb.py\", line 281, in _fixed_getinnerframes\n",
      "    records = fix_frame_records_filenames(inspect.getinnerframes(etb, context))\n",
      "  File \"/Users/cyanaspect/opt/anaconda3/envs/ml/lib/python3.7/inspect.py\", line 1502, in getinnerframes\n",
      "    frameinfo = (tb.tb_frame,) + getframeinfo(tb, context)\n",
      "  File \"/Users/cyanaspect/opt/anaconda3/envs/ml/lib/python3.7/inspect.py\", line 1460, in getframeinfo\n",
      "    filename = getsourcefile(frame) or getfile(frame)\n",
      "  File \"/Users/cyanaspect/opt/anaconda3/envs/ml/lib/python3.7/inspect.py\", line 696, in getsourcefile\n",
      "    if getattr(getmodule(object, filename), '__loader__', None) is not None:\n",
      "  File \"/Users/cyanaspect/opt/anaconda3/envs/ml/lib/python3.7/inspect.py\", line 733, in getmodule\n",
      "    if ismodule(module) and hasattr(module, '__file__'):\n",
      "  File \"/Users/cyanaspect/opt/anaconda3/envs/ml/lib/python3.7/site-packages/tensorflow/__init__.py\", line 50, in __getattr__\n",
      "    module = self._load()\n",
      "  File \"/Users/cyanaspect/opt/anaconda3/envs/ml/lib/python3.7/site-packages/tensorflow/__init__.py\", line 44, in _load\n",
      "    module = _importlib.import_module(self.__name__)\n",
      "  File \"/Users/cyanaspect/opt/anaconda3/envs/ml/lib/python3.7/importlib/__init__.py\", line 127, in import_module\n",
      "    return _bootstrap._gcd_import(name[level:], package, level)\n",
      "  File \"<frozen importlib._bootstrap>\", line 1006, in _gcd_import\n",
      "  File \"<frozen importlib._bootstrap>\", line 983, in _find_and_load\n",
      "  File \"<frozen importlib._bootstrap>\", line 953, in _find_and_load_unlocked\n",
      "  File \"<frozen importlib._bootstrap>\", line 219, in _call_with_frames_removed\n",
      "  File \"<frozen importlib._bootstrap>\", line 1006, in _gcd_import\n",
      "  File \"<frozen importlib._bootstrap>\", line 983, in _find_and_load\n",
      "  File \"<frozen importlib._bootstrap>\", line 967, in _find_and_load_unlocked\n",
      "  File \"<frozen importlib._bootstrap>\", line 677, in _load_unlocked\n",
      "  File \"<frozen importlib._bootstrap_external>\", line 728, in exec_module\n",
      "  File \"<frozen importlib._bootstrap>\", line 219, in _call_with_frames_removed\n",
      "  File \"/Users/cyanaspect/opt/anaconda3/envs/ml/lib/python3.7/site-packages/tensorflow_core/__init__.py\", line 42, in <module>\n",
      "    from . _api.v2 import audio\n",
      "  File \"/Users/cyanaspect/opt/anaconda3/envs/ml/lib/python3.7/site-packages/tensorflow_core/_api/v2/audio/__init__.py\", line 10, in <module>\n",
      "    from tensorflow.python.ops.gen_audio_ops import decode_wav\n",
      "  File \"/Users/cyanaspect/opt/anaconda3/envs/ml/lib/python3.7/site-packages/tensorflow_core/python/ops/gen_audio_ops.py\", line 10, in <module>\n",
      "    from tensorflow.python import pywrap_tensorflow as _pywrap_tensorflow\n",
      "  File \"/Users/cyanaspect/opt/anaconda3/envs/ml/lib/python3.7/site-packages/tensorflow/__init__.py\", line 50, in __getattr__\n",
      "    module = self._load()\n",
      "  File \"/Users/cyanaspect/opt/anaconda3/envs/ml/lib/python3.7/site-packages/tensorflow/__init__.py\", line 44, in _load\n",
      "    module = _importlib.import_module(self.__name__)\n",
      "  File \"/Users/cyanaspect/opt/anaconda3/envs/ml/lib/python3.7/importlib/__init__.py\", line 127, in import_module\n",
      "    return _bootstrap._gcd_import(name[level:], package, level)\n",
      "  File \"/Users/cyanaspect/opt/anaconda3/envs/ml/lib/python3.7/site-packages/tensorflow_core/python/__init__.py\", line 49, in <module>\n",
      "    from tensorflow.python import pywrap_tensorflow\n",
      "  File \"/Users/cyanaspect/opt/anaconda3/envs/ml/lib/python3.7/site-packages/tensorflow_core/python/pywrap_tensorflow.py\", line 74, in <module>\n",
      "    raise ImportError(msg)\n",
      "ImportError: Traceback (most recent call last):\n",
      "  File \"/Users/cyanaspect/opt/anaconda3/envs/ml/lib/python3.7/site-packages/IPython/core/interactiveshell.py\", line 3457, in run_code\n",
      "    exec(code_obj, self.user_global_ns, self.user_ns)\n",
      "  File \"/var/folders/kg/5sdfljwd58339hwyr4gl3bvh0000gn/T/ipykernel_9521/3680598616.py\", line 1, in <module>\n",
      "    clusters_for_each_window[0][4]\n",
      "IndexError: list index out of range\n",
      "\n",
      "During handling of the above exception, another exception occurred:\n",
      "\n",
      "Traceback (most recent call last):\n",
      "  File \"/Users/cyanaspect/opt/anaconda3/envs/ml/lib/python3.7/site-packages/IPython/core/interactiveshell.py\", line 2077, in showtraceback\n",
      "    stb = value._render_traceback_()\n",
      "AttributeError: 'IndexError' object has no attribute '_render_traceback_'\n",
      "\n",
      "During handling of the above exception, another exception occurred:\n",
      "\n",
      "Traceback (most recent call last):\n",
      "  File \"/Users/cyanaspect/opt/anaconda3/envs/ml/lib/python3.7/site-packages/IPython/core/interactiveshell.py\", line 3377, in run_ast_nodes\n",
      "    if (await self.run_code(code, result,  async_=asy)):\n",
      "  File \"/Users/cyanaspect/opt/anaconda3/envs/ml/lib/python3.7/site-packages/IPython/core/interactiveshell.py\", line 3474, in run_code\n",
      "    self.showtraceback(running_compiled_code=True)\n",
      "  File \"/Users/cyanaspect/opt/anaconda3/envs/ml/lib/python3.7/site-packages/IPython/core/interactiveshell.py\", line 2080, in showtraceback\n",
      "    value, tb, tb_offset=tb_offset)\n",
      "  File \"/Users/cyanaspect/opt/anaconda3/envs/ml/lib/python3.7/site-packages/IPython/core/ultratb.py\", line 1368, in structured_traceback\n",
      "    self, etype, value, tb, tb_offset, number_of_lines_of_context)\n",
      "  File \"/Users/cyanaspect/opt/anaconda3/envs/ml/lib/python3.7/site-packages/IPython/core/ultratb.py\", line 1268, in structured_traceback\n",
      "    self, etype, value, tb, tb_offset, number_of_lines_of_context\n",
      "  File \"/Users/cyanaspect/opt/anaconda3/envs/ml/lib/python3.7/site-packages/IPython/core/ultratb.py\", line 1125, in structured_traceback\n",
      "    tb_offset)\n",
      "  File \"/Users/cyanaspect/opt/anaconda3/envs/ml/lib/python3.7/site-packages/IPython/core/ultratb.py\", line 1082, in format_exception_as_a_whole\n",
      "    last_unique, recursion_repeat = find_recursion(orig_etype, evalue, records)\n",
      "  File \"/Users/cyanaspect/opt/anaconda3/envs/ml/lib/python3.7/site-packages/IPython/core/ultratb.py\", line 382, in find_recursion\n",
      "    return len(records), 0\n",
      "TypeError: object of type 'NoneType' has no len()\n",
      "\n",
      "During handling of the above exception, another exception occurred:\n",
      "\n",
      "Traceback (most recent call last):\n",
      "  File \"/Users/cyanaspect/opt/anaconda3/envs/ml/lib/python3.7/site-packages/IPython/core/interactiveshell.py\", line 2077, in showtraceback\n",
      "    stb = value._render_traceback_()\n",
      "AttributeError: 'TypeError' object has no attribute '_render_traceback_'\n",
      "\n",
      "During handling of the above exception, another exception occurred:\n",
      "\n",
      "Traceback (most recent call last):\n",
      "  File \"/Users/cyanaspect/opt/anaconda3/envs/ml/lib/python3.7/site-packages/tensorflow_core/python/pywrap_tensorflow.py\", line 58, in <module>\n",
      "    from tensorflow.python.pywrap_tensorflow_internal import *\n",
      "  File \"/Users/cyanaspect/opt/anaconda3/envs/ml/lib/python3.7/site-packages/tensorflow_core/python/pywrap_tensorflow_internal.py\", line 28, in <module>\n",
      "    _pywrap_tensorflow_internal = swig_import_helper()\n",
      "  File \"/Users/cyanaspect/opt/anaconda3/envs/ml/lib/python3.7/site-packages/tensorflow_core/python/pywrap_tensorflow_internal.py\", line 24, in swig_import_helper\n",
      "    _mod = imp.load_module('_pywrap_tensorflow_internal', fp, pathname, description)\n",
      "  File \"/Users/cyanaspect/opt/anaconda3/envs/ml/lib/python3.7/imp.py\", line 242, in load_module\n",
      "    return load_dynamic(name, filename, file)\n",
      "  File \"/Users/cyanaspect/opt/anaconda3/envs/ml/lib/python3.7/imp.py\", line 342, in load_dynamic\n",
      "    return _load(spec)\n",
      "ImportError: dlopen(/Users/cyanaspect/opt/anaconda3/envs/ml/lib/python3.7/site-packages/tensorflow_core/python/_pywrap_tensorflow_internal.so, 0x0006): Library not loaded: @rpath/libtensorflow_framework.2.dylib\n",
      "  Referenced from: /Users/cyanaspect/opt/anaconda3/envs/ml/lib/python3.7/site-packages/tensorflow_core/python/_pywrap_tensorflow_internal.so\n",
      "  Reason: tried: '/Users/cyanaspect/opt/anaconda3/envs/ml/lib/python3.7/site-packages/tensorflow_core/python/../../_solib_darwin/_U_S_Stensorflow_Spython_C_Upywrap_Utensorflow_Uinternal.so___Utensorflow/libtensorflow_framework.2.dylib' (no such file), '/Users/cyanaspect/opt/anaconda3/envs/ml/lib/python3.7/site-packages/tensorflow_core/python/../../_solib_darwin/_U@mkl_Udarwin_S_S_Cmkl_Ulibs_Udarwin___Uexternal_Smkl_Udarwin_Slib/libtensorflow_framework.2.dylib' (no such file), '/Users/cyanaspect/opt/anaconda3/envs/ml/lib/python3.7/site-packages/tensorflow_core/python/libtensorflow_framework.2.dylib' (no such file), '/Users/cyanaspect/opt/anaconda3/envs/ml/lib/python3.7/site-packages/tensorflow_core/python/../libtensorflow_framework.2.dylib' (no such file), '/Users/cyanaspect/opt/anaconda3/envs/ml/lib/python3.7/site-packages/tensorflow_core/python/../../../../libtensorflow_framework.2.dylib' (no such file), '/Users/cyanaspect/opt/anaconda3/envs/ml/lib/python3.7/site-packages/tensorflow_core/python/../../_solib_darwin/_U_S_Stensorflow_Spython_C_Upywrap_Utensorflow_Uinternal.so___Utensorflow/libtensorflow_framework.2.dylib' (no such file), '/Users/cyanaspect/opt/anaconda3/envs/ml/lib/python3.7/site-packages/tensorflow_core/python/../../_solib_darwin/_U@mkl_Udarwin_S_S_Cmkl_Ulibs_Udarwin___Uexternal_Smkl_Udarwin_Slib/libtensorflow_framework.2.dylib' (no such file), '/Users/cyanaspect/opt/anaconda3/envs/ml/lib/python3.7/site-packages/tensorflow_core/python/libtensorflow_framework.2.dylib' (no such file), '/Users/cyanaspect/opt/anaconda3/envs/ml/lib/python3.7/site-packages/tensorflow_core/python/../libtensorflow_framework.2.dylib' (no such file), '/Users/cyanaspect/opt/anaconda3/envs/ml/lib/python3.7/site-packages/tensorflow_core/python/../../../../libtensorflow_framework.2.dylib' (no such file), '/Users/cyanaspect/opt/anaconda3/envs/ml/bin/../lib/libtensorflow_framework.2.dylib' (no such file), '/Users/cyanaspect/opt/anaconda3/envs/ml/bin/../lib/libtensorflow_framework.2.dylib' (no such file), '/usr/local/lib/libtensorflow_framework.2.dylib' (no such file), '/usr/lib/libtensorflow_framework.2.dylib' (no such file)\n",
      "\n",
      "\n",
      "Failed to load the native TensorFlow runtime.\n",
      "\n",
      "See https://www.tensorflow.org/install/errors\n",
      "\n",
      "for some common reasons and solutions.  Include the entire stack trace\n",
      "above this error message when asking for help.\n",
      "Traceback (most recent call last):\n",
      "  File \"/Users/cyanaspect/opt/anaconda3/envs/ml/lib/python3.7/site-packages/IPython/core/interactiveshell.py\", line 3457, in run_code\n",
      "    exec(code_obj, self.user_global_ns, self.user_ns)\n",
      "  File \"/var/folders/kg/5sdfljwd58339hwyr4gl3bvh0000gn/T/ipykernel_9521/3680598616.py\", line 1, in <module>\n",
      "    clusters_for_each_window[0][4]\n",
      "IndexError: list index out of range\n",
      "\n",
      "During handling of the above exception, another exception occurred:\n",
      "\n",
      "Traceback (most recent call last):\n",
      "  File \"/Users/cyanaspect/opt/anaconda3/envs/ml/lib/python3.7/site-packages/IPython/core/interactiveshell.py\", line 2077, in showtraceback\n",
      "    stb = value._render_traceback_()\n",
      "AttributeError: 'IndexError' object has no attribute '_render_traceback_'\n",
      "\n",
      "During handling of the above exception, another exception occurred:\n",
      "\n",
      "Traceback (most recent call last):\n",
      "  File \"/Users/cyanaspect/opt/anaconda3/envs/ml/lib/python3.7/site-packages/IPython/core/interactiveshell.py\", line 3377, in run_ast_nodes\n",
      "    if (await self.run_code(code, result,  async_=asy)):\n",
      "  File \"/Users/cyanaspect/opt/anaconda3/envs/ml/lib/python3.7/site-packages/IPython/core/interactiveshell.py\", line 3474, in run_code\n",
      "    self.showtraceback(running_compiled_code=True)\n",
      "  File \"/Users/cyanaspect/opt/anaconda3/envs/ml/lib/python3.7/site-packages/IPython/core/interactiveshell.py\", line 2080, in showtraceback\n",
      "    value, tb, tb_offset=tb_offset)\n",
      "  File \"/Users/cyanaspect/opt/anaconda3/envs/ml/lib/python3.7/site-packages/IPython/core/ultratb.py\", line 1368, in structured_traceback\n",
      "    self, etype, value, tb, tb_offset, number_of_lines_of_context)\n",
      "  File \"/Users/cyanaspect/opt/anaconda3/envs/ml/lib/python3.7/site-packages/IPython/core/ultratb.py\", line 1268, in structured_traceback\n",
      "    self, etype, value, tb, tb_offset, number_of_lines_of_context\n",
      "  File \"/Users/cyanaspect/opt/anaconda3/envs/ml/lib/python3.7/site-packages/IPython/core/ultratb.py\", line 1125, in structured_traceback\n",
      "    tb_offset)\n",
      "  File \"/Users/cyanaspect/opt/anaconda3/envs/ml/lib/python3.7/site-packages/IPython/core/ultratb.py\", line 1082, in format_exception_as_a_whole\n",
      "    last_unique, recursion_repeat = find_recursion(orig_etype, evalue, records)\n",
      "  File \"/Users/cyanaspect/opt/anaconda3/envs/ml/lib/python3.7/site-packages/IPython/core/ultratb.py\", line 382, in find_recursion\n",
      "    return len(records), 0\n",
      "TypeError: object of type 'NoneType' has no len()\n",
      "\n",
      "During handling of the above exception, another exception occurred:\n",
      "\n",
      "Traceback (most recent call last):\n",
      "  File \"/Users/cyanaspect/opt/anaconda3/envs/ml/lib/python3.7/site-packages/IPython/core/interactiveshell.py\", line 2077, in showtraceback\n",
      "    stb = value._render_traceback_()\n",
      "AttributeError: 'TypeError' object has no attribute '_render_traceback_'\n",
      "\n",
      "During handling of the above exception, another exception occurred:\n",
      "\n",
      "Traceback (most recent call last):\n",
      "  File \"/Users/cyanaspect/opt/anaconda3/envs/ml/lib/python3.7/site-packages/IPython/core/interactiveshell.py\", line 2960, in _run_cell\n",
      "    return runner(coro)\n",
      "  File \"/Users/cyanaspect/opt/anaconda3/envs/ml/lib/python3.7/site-packages/IPython/core/async_helpers.py\", line 78, in _pseudo_sync_runner\n",
      "    coro.send(None)\n",
      "  File \"/Users/cyanaspect/opt/anaconda3/envs/ml/lib/python3.7/site-packages/IPython/core/interactiveshell.py\", line 3186, in run_cell_async\n",
      "    interactivity=interactivity, compiler=compiler, result=result)\n",
      "  File \"/Users/cyanaspect/opt/anaconda3/envs/ml/lib/python3.7/site-packages/IPython/core/interactiveshell.py\", line 3396, in run_ast_nodes\n",
      "    self.showtraceback()\n",
      "  File \"/Users/cyanaspect/opt/anaconda3/envs/ml/lib/python3.7/site-packages/IPython/core/interactiveshell.py\", line 2080, in showtraceback\n",
      "    value, tb, tb_offset=tb_offset)\n",
      "  File \"/Users/cyanaspect/opt/anaconda3/envs/ml/lib/python3.7/site-packages/IPython/core/ultratb.py\", line 1368, in structured_traceback\n",
      "    self, etype, value, tb, tb_offset, number_of_lines_of_context)\n",
      "  File \"/Users/cyanaspect/opt/anaconda3/envs/ml/lib/python3.7/site-packages/IPython/core/ultratb.py\", line 1268, in structured_traceback\n",
      "    self, etype, value, tb, tb_offset, number_of_lines_of_context\n",
      "  File \"/Users/cyanaspect/opt/anaconda3/envs/ml/lib/python3.7/site-packages/IPython/core/ultratb.py\", line 1143, in structured_traceback\n",
      "    chained_exceptions_tb_offset)\n",
      "  File \"/Users/cyanaspect/opt/anaconda3/envs/ml/lib/python3.7/site-packages/IPython/core/ultratb.py\", line 1082, in format_exception_as_a_whole\n",
      "    last_unique, recursion_repeat = find_recursion(orig_etype, evalue, records)\n",
      "  File \"/Users/cyanaspect/opt/anaconda3/envs/ml/lib/python3.7/site-packages/IPython/core/ultratb.py\", line 382, in find_recursion\n",
      "    return len(records), 0\n",
      "TypeError: object of type 'NoneType' has no len()\n",
      "\n",
      "During handling of the above exception, another exception occurred:\n",
      "\n",
      "Traceback (most recent call last):\n",
      "  File \"/Users/cyanaspect/opt/anaconda3/envs/ml/lib/python3.7/site-packages/IPython/core/interactiveshell.py\", line 2077, in showtraceback\n",
      "    stb = value._render_traceback_()\n",
      "AttributeError: 'TypeError' object has no attribute '_render_traceback_'\n",
      "\n",
      "During handling of the above exception, another exception occurred:\n",
      "\n",
      "Traceback (most recent call last):\n",
      "  File \"/Users/cyanaspect/opt/anaconda3/envs/ml/lib/python3.7/site-packages/tensorflow_core/python/pywrap_tensorflow.py\", line 58, in <module>\n",
      "    from tensorflow.python.pywrap_tensorflow_internal import *\n",
      "  File \"/Users/cyanaspect/opt/anaconda3/envs/ml/lib/python3.7/site-packages/tensorflow_core/python/pywrap_tensorflow_internal.py\", line 28, in <module>\n",
      "    _pywrap_tensorflow_internal = swig_import_helper()\n",
      "  File \"/Users/cyanaspect/opt/anaconda3/envs/ml/lib/python3.7/site-packages/tensorflow_core/python/pywrap_tensorflow_internal.py\", line 24, in swig_import_helper\n",
      "    _mod = imp.load_module('_pywrap_tensorflow_internal', fp, pathname, description)\n",
      "  File \"/Users/cyanaspect/opt/anaconda3/envs/ml/lib/python3.7/imp.py\", line 242, in load_module\n",
      "    return load_dynamic(name, filename, file)\n",
      "  File \"/Users/cyanaspect/opt/anaconda3/envs/ml/lib/python3.7/imp.py\", line 342, in load_dynamic\n",
      "    return _load(spec)\n",
      "ImportError: dlopen(/Users/cyanaspect/opt/anaconda3/envs/ml/lib/python3.7/site-packages/tensorflow_core/python/_pywrap_tensorflow_internal.so, 0x0006): Library not loaded: @rpath/libtensorflow_framework.2.dylib\n",
      "  Referenced from: /Users/cyanaspect/opt/anaconda3/envs/ml/lib/python3.7/site-packages/tensorflow_core/python/_pywrap_tensorflow_internal.so\n",
      "  Reason: tried: '/Users/cyanaspect/opt/anaconda3/envs/ml/lib/python3.7/site-packages/tensorflow_core/python/../../_solib_darwin/_U_S_Stensorflow_Spython_C_Upywrap_Utensorflow_Uinternal.so___Utensorflow/libtensorflow_framework.2.dylib' (no such file), '/Users/cyanaspect/opt/anaconda3/envs/ml/lib/python3.7/site-packages/tensorflow_core/python/../../_solib_darwin/_U@mkl_Udarwin_S_S_Cmkl_Ulibs_Udarwin___Uexternal_Smkl_Udarwin_Slib/libtensorflow_framework.2.dylib' (no such file), '/Users/cyanaspect/opt/anaconda3/envs/ml/lib/python3.7/site-packages/tensorflow_core/python/libtensorflow_framework.2.dylib' (no such file), '/Users/cyanaspect/opt/anaconda3/envs/ml/lib/python3.7/site-packages/tensorflow_core/python/../libtensorflow_framework.2.dylib' (no such file), '/Users/cyanaspect/opt/anaconda3/envs/ml/lib/python3.7/site-packages/tensorflow_core/python/../../../../libtensorflow_framework.2.dylib' (no such file), '/Users/cyanaspect/opt/anaconda3/envs/ml/lib/python3.7/site-packages/tensorflow_core/python/../../_solib_darwin/_U_S_Stensorflow_Spython_C_Upywrap_Utensorflow_Uinternal.so___Utensorflow/libtensorflow_framework.2.dylib' (no such file), '/Users/cyanaspect/opt/anaconda3/envs/ml/lib/python3.7/site-packages/tensorflow_core/python/../../_solib_darwin/_U@mkl_Udarwin_S_S_Cmkl_Ulibs_Udarwin___Uexternal_Smkl_Udarwin_Slib/libtensorflow_framework.2.dylib' (no such file), '/Users/cyanaspect/opt/anaconda3/envs/ml/lib/python3.7/site-packages/tensorflow_core/python/libtensorflow_framework.2.dylib' (no such file), '/Users/cyanaspect/opt/anaconda3/envs/ml/lib/python3.7/site-packages/tensorflow_core/python/../libtensorflow_framework.2.dylib' (no such file), '/Users/cyanaspect/opt/anaconda3/envs/ml/lib/python3.7/site-packages/tensorflow_core/python/../../../../libtensorflow_framework.2.dylib' (no such file), '/Users/cyanaspect/opt/anaconda3/envs/ml/bin/../lib/libtensorflow_framework.2.dylib' (no such file), '/Users/cyanaspect/opt/anaconda3/envs/ml/bin/../lib/libtensorflow_framework.2.dylib' (no such file), '/usr/local/lib/libtensorflow_framework.2.dylib' (no such file), '/usr/lib/libtensorflow_framework.2.dylib' (no such file)\n",
      "\n",
      "During handling of the above exception, another exception occurred:\n",
      "\n",
      "Traceback (most recent call last):\n",
      "  File \"/Users/cyanaspect/opt/anaconda3/envs/ml/lib/python3.7/site-packages/IPython/core/ultratb.py\", line 1101, in get_records\n",
      "    return _fixed_getinnerframes(etb, number_of_lines_of_context, tb_offset)\n",
      "  File \"/Users/cyanaspect/opt/anaconda3/envs/ml/lib/python3.7/site-packages/IPython/core/ultratb.py\", line 248, in wrapped\n",
      "    return f(*args, **kwargs)\n",
      "  File \"/Users/cyanaspect/opt/anaconda3/envs/ml/lib/python3.7/site-packages/IPython/core/ultratb.py\", line 281, in _fixed_getinnerframes\n",
      "    records = fix_frame_records_filenames(inspect.getinnerframes(etb, context))\n",
      "  File \"/Users/cyanaspect/opt/anaconda3/envs/ml/lib/python3.7/inspect.py\", line 1502, in getinnerframes\n",
      "    frameinfo = (tb.tb_frame,) + getframeinfo(tb, context)\n",
      "  File \"/Users/cyanaspect/opt/anaconda3/envs/ml/lib/python3.7/inspect.py\", line 1460, in getframeinfo\n",
      "    filename = getsourcefile(frame) or getfile(frame)\n",
      "  File \"/Users/cyanaspect/opt/anaconda3/envs/ml/lib/python3.7/inspect.py\", line 696, in getsourcefile\n",
      "    if getattr(getmodule(object, filename), '__loader__', None) is not None:\n",
      "  File \"/Users/cyanaspect/opt/anaconda3/envs/ml/lib/python3.7/inspect.py\", line 733, in getmodule\n",
      "    if ismodule(module) and hasattr(module, '__file__'):\n",
      "  File \"/Users/cyanaspect/opt/anaconda3/envs/ml/lib/python3.7/site-packages/tensorflow/__init__.py\", line 50, in __getattr__\n",
      "    module = self._load()\n",
      "  File \"/Users/cyanaspect/opt/anaconda3/envs/ml/lib/python3.7/site-packages/tensorflow/__init__.py\", line 44, in _load\n",
      "    module = _importlib.import_module(self.__name__)\n",
      "  File \"/Users/cyanaspect/opt/anaconda3/envs/ml/lib/python3.7/importlib/__init__.py\", line 127, in import_module\n",
      "    return _bootstrap._gcd_import(name[level:], package, level)\n",
      "  File \"<frozen importlib._bootstrap>\", line 1006, in _gcd_import\n",
      "  File \"<frozen importlib._bootstrap>\", line 983, in _find_and_load\n",
      "  File \"<frozen importlib._bootstrap>\", line 953, in _find_and_load_unlocked\n",
      "  File \"<frozen importlib._bootstrap>\", line 219, in _call_with_frames_removed\n",
      "  File \"<frozen importlib._bootstrap>\", line 1006, in _gcd_import\n",
      "  File \"<frozen importlib._bootstrap>\", line 983, in _find_and_load\n",
      "  File \"<frozen importlib._bootstrap>\", line 967, in _find_and_load_unlocked\n",
      "  File \"<frozen importlib._bootstrap>\", line 677, in _load_unlocked\n",
      "  File \"<frozen importlib._bootstrap_external>\", line 728, in exec_module\n",
      "  File \"<frozen importlib._bootstrap>\", line 219, in _call_with_frames_removed\n",
      "  File \"/Users/cyanaspect/opt/anaconda3/envs/ml/lib/python3.7/site-packages/tensorflow_core/__init__.py\", line 42, in <module>\n",
      "    from . _api.v2 import audio\n",
      "  File \"/Users/cyanaspect/opt/anaconda3/envs/ml/lib/python3.7/site-packages/tensorflow_core/_api/v2/audio/__init__.py\", line 10, in <module>\n",
      "    from tensorflow.python.ops.gen_audio_ops import decode_wav\n",
      "  File \"/Users/cyanaspect/opt/anaconda3/envs/ml/lib/python3.7/site-packages/tensorflow_core/python/ops/gen_audio_ops.py\", line 10, in <module>\n",
      "    from tensorflow.python import pywrap_tensorflow as _pywrap_tensorflow\n",
      "  File \"/Users/cyanaspect/opt/anaconda3/envs/ml/lib/python3.7/site-packages/tensorflow/__init__.py\", line 50, in __getattr__\n",
      "    module = self._load()\n",
      "  File \"/Users/cyanaspect/opt/anaconda3/envs/ml/lib/python3.7/site-packages/tensorflow/__init__.py\", line 44, in _load\n",
      "    module = _importlib.import_module(self.__name__)\n",
      "  File \"/Users/cyanaspect/opt/anaconda3/envs/ml/lib/python3.7/importlib/__init__.py\", line 127, in import_module\n",
      "    return _bootstrap._gcd_import(name[level:], package, level)\n",
      "  File \"/Users/cyanaspect/opt/anaconda3/envs/ml/lib/python3.7/site-packages/tensorflow_core/python/__init__.py\", line 49, in <module>\n",
      "    from tensorflow.python import pywrap_tensorflow\n",
      "  File \"/Users/cyanaspect/opt/anaconda3/envs/ml/lib/python3.7/site-packages/tensorflow_core/python/pywrap_tensorflow.py\", line 74, in <module>\n",
      "    raise ImportError(msg)\n",
      "ImportError: Traceback (most recent call last):\n",
      "  File \"/Users/cyanaspect/opt/anaconda3/envs/ml/lib/python3.7/site-packages/IPython/core/interactiveshell.py\", line 3457, in run_code\n",
      "    exec(code_obj, self.user_global_ns, self.user_ns)\n",
      "  File \"/var/folders/kg/5sdfljwd58339hwyr4gl3bvh0000gn/T/ipykernel_9521/3680598616.py\", line 1, in <module>\n",
      "    clusters_for_each_window[0][4]\n",
      "IndexError: list index out of range\n",
      "\n",
      "During handling of the above exception, another exception occurred:\n",
      "\n",
      "Traceback (most recent call last):\n",
      "  File \"/Users/cyanaspect/opt/anaconda3/envs/ml/lib/python3.7/site-packages/IPython/core/interactiveshell.py\", line 2077, in showtraceback\n",
      "    stb = value._render_traceback_()\n",
      "AttributeError: 'IndexError' object has no attribute '_render_traceback_'\n",
      "\n",
      "During handling of the above exception, another exception occurred:\n",
      "\n",
      "Traceback (most recent call last):\n",
      "  File \"/Users/cyanaspect/opt/anaconda3/envs/ml/lib/python3.7/site-packages/IPython/core/interactiveshell.py\", line 3377, in run_ast_nodes\n",
      "    if (await self.run_code(code, result,  async_=asy)):\n",
      "  File \"/Users/cyanaspect/opt/anaconda3/envs/ml/lib/python3.7/site-packages/IPython/core/interactiveshell.py\", line 3474, in run_code\n",
      "    self.showtraceback(running_compiled_code=True)\n",
      "  File \"/Users/cyanaspect/opt/anaconda3/envs/ml/lib/python3.7/site-packages/IPython/core/interactiveshell.py\", line 2080, in showtraceback\n",
      "    value, tb, tb_offset=tb_offset)\n",
      "  File \"/Users/cyanaspect/opt/anaconda3/envs/ml/lib/python3.7/site-packages/IPython/core/ultratb.py\", line 1368, in structured_traceback\n",
      "    self, etype, value, tb, tb_offset, number_of_lines_of_context)\n",
      "  File \"/Users/cyanaspect/opt/anaconda3/envs/ml/lib/python3.7/site-packages/IPython/core/ultratb.py\", line 1268, in structured_traceback\n",
      "    self, etype, value, tb, tb_offset, number_of_lines_of_context\n",
      "  File \"/Users/cyanaspect/opt/anaconda3/envs/ml/lib/python3.7/site-packages/IPython/core/ultratb.py\", line 1125, in structured_traceback\n",
      "    tb_offset)\n",
      "  File \"/Users/cyanaspect/opt/anaconda3/envs/ml/lib/python3.7/site-packages/IPython/core/ultratb.py\", line 1082, in format_exception_as_a_whole\n",
      "    last_unique, recursion_repeat = find_recursion(orig_etype, evalue, records)\n",
      "  File \"/Users/cyanaspect/opt/anaconda3/envs/ml/lib/python3.7/site-packages/IPython/core/ultratb.py\", line 382, in find_recursion\n",
      "    return len(records), 0\n",
      "TypeError: object of type 'NoneType' has no len()\n",
      "\n",
      "During handling of the above exception, another exception occurred:\n",
      "\n",
      "Traceback (most recent call last):\n",
      "  File \"/Users/cyanaspect/opt/anaconda3/envs/ml/lib/python3.7/site-packages/IPython/core/interactiveshell.py\", line 2077, in showtraceback\n",
      "    stb = value._render_traceback_()\n",
      "AttributeError: 'TypeError' object has no attribute '_render_traceback_'\n",
      "\n",
      "During handling of the above exception, another exception occurred:\n",
      "\n",
      "Traceback (most recent call last):\n",
      "  File \"/Users/cyanaspect/opt/anaconda3/envs/ml/lib/python3.7/site-packages/IPython/core/interactiveshell.py\", line 2960, in _run_cell\n",
      "    return runner(coro)\n",
      "  File \"/Users/cyanaspect/opt/anaconda3/envs/ml/lib/python3.7/site-packages/IPython/core/async_helpers.py\", line 78, in _pseudo_sync_runner\n",
      "    coro.send(None)\n",
      "  File \"/Users/cyanaspect/opt/anaconda3/envs/ml/lib/python3.7/site-packages/IPython/core/interactiveshell.py\", line 3186, in run_cell_async\n",
      "    interactivity=interactivity, compiler=compiler, result=result)\n",
      "  File \"/Users/cyanaspect/opt/anaconda3/envs/ml/lib/python3.7/site-packages/IPython/core/interactiveshell.py\", line 3396, in run_ast_nodes\n",
      "    self.showtraceback()\n",
      "  File \"/Users/cyanaspect/opt/anaconda3/envs/ml/lib/python3.7/site-packages/IPython/core/interactiveshell.py\", line 2080, in showtraceback\n",
      "    value, tb, tb_offset=tb_offset)\n",
      "  File \"/Users/cyanaspect/opt/anaconda3/envs/ml/lib/python3.7/site-packages/IPython/core/ultratb.py\", line 1368, in structured_traceback\n",
      "    self, etype, value, tb, tb_offset, number_of_lines_of_context)\n",
      "  File \"/Users/cyanaspect/opt/anaconda3/envs/ml/lib/python3.7/site-packages/IPython/core/ultratb.py\", line 1268, in structured_traceback\n",
      "    self, etype, value, tb, tb_offset, number_of_lines_of_context\n",
      "  File \"/Users/cyanaspect/opt/anaconda3/envs/ml/lib/python3.7/site-packages/IPython/core/ultratb.py\", line 1143, in structured_traceback\n",
      "    chained_exceptions_tb_offset)\n",
      "  File \"/Users/cyanaspect/opt/anaconda3/envs/ml/lib/python3.7/site-packages/IPython/core/ultratb.py\", line 1082, in format_exception_as_a_whole\n",
      "    last_unique, recursion_repeat = find_recursion(orig_etype, evalue, records)\n",
      "  File \"/Users/cyanaspect/opt/anaconda3/envs/ml/lib/python3.7/site-packages/IPython/core/ultratb.py\", line 382, in find_recursion\n",
      "    return len(records), 0\n",
      "TypeError: object of type 'NoneType' has no len()\n",
      "\n",
      "During handling of the above exception, another exception occurred:\n",
      "\n",
      "Traceback (most recent call last):\n",
      "  File \"/Users/cyanaspect/opt/anaconda3/envs/ml/lib/python3.7/site-packages/IPython/core/interactiveshell.py\", line 2077, in showtraceback\n",
      "    stb = value._render_traceback_()\n",
      "AttributeError: 'TypeError' object has no attribute '_render_traceback_'\n",
      "\n",
      "During handling of the above exception, another exception occurred:\n",
      "\n",
      "Traceback (most recent call last):\n",
      "  File \"/Users/cyanaspect/opt/anaconda3/envs/ml/lib/python3.7/site-packages/tensorflow_core/python/pywrap_tensorflow.py\", line 58, in <module>\n",
      "    from tensorflow.python.pywrap_tensorflow_internal import *\n",
      "  File \"/Users/cyanaspect/opt/anaconda3/envs/ml/lib/python3.7/site-packages/tensorflow_core/python/pywrap_tensorflow_internal.py\", line 28, in <module>\n",
      "    _pywrap_tensorflow_internal = swig_import_helper()\n",
      "  File \"/Users/cyanaspect/opt/anaconda3/envs/ml/lib/python3.7/site-packages/tensorflow_core/python/pywrap_tensorflow_internal.py\", line 24, in swig_import_helper\n",
      "    _mod = imp.load_module('_pywrap_tensorflow_internal', fp, pathname, description)\n",
      "  File \"/Users/cyanaspect/opt/anaconda3/envs/ml/lib/python3.7/imp.py\", line 242, in load_module\n",
      "    return load_dynamic(name, filename, file)\n",
      "  File \"/Users/cyanaspect/opt/anaconda3/envs/ml/lib/python3.7/imp.py\", line 342, in load_dynamic\n",
      "    return _load(spec)\n",
      "ImportError: dlopen(/Users/cyanaspect/opt/anaconda3/envs/ml/lib/python3.7/site-packages/tensorflow_core/python/_pywrap_tensorflow_internal.so, 0x0006): Library not loaded: @rpath/libtensorflow_framework.2.dylib\n",
      "  Referenced from: /Users/cyanaspect/opt/anaconda3/envs/ml/lib/python3.7/site-packages/tensorflow_core/python/_pywrap_tensorflow_internal.so\n",
      "  Reason: tried: '/Users/cyanaspect/opt/anaconda3/envs/ml/lib/python3.7/site-packages/tensorflow_core/python/../../_solib_darwin/_U_S_Stensorflow_Spython_C_Upywrap_Utensorflow_Uinternal.so___Utensorflow/libtensorflow_framework.2.dylib' (no such file), '/Users/cyanaspect/opt/anaconda3/envs/ml/lib/python3.7/site-packages/tensorflow_core/python/../../_solib_darwin/_U@mkl_Udarwin_S_S_Cmkl_Ulibs_Udarwin___Uexternal_Smkl_Udarwin_Slib/libtensorflow_framework.2.dylib' (no such file), '/Users/cyanaspect/opt/anaconda3/envs/ml/lib/python3.7/site-packages/tensorflow_core/python/libtensorflow_framework.2.dylib' (no such file), '/Users/cyanaspect/opt/anaconda3/envs/ml/lib/python3.7/site-packages/tensorflow_core/python/../libtensorflow_framework.2.dylib' (no such file), '/Users/cyanaspect/opt/anaconda3/envs/ml/lib/python3.7/site-packages/tensorflow_core/python/../../../../libtensorflow_framework.2.dylib' (no such file), '/Users/cyanaspect/opt/anaconda3/envs/ml/lib/python3.7/site-packages/tensorflow_core/python/../../_solib_darwin/_U_S_Stensorflow_Spython_C_Upywrap_Utensorflow_Uinternal.so___Utensorflow/libtensorflow_framework.2.dylib' (no such file), '/Users/cyanaspect/opt/anaconda3/envs/ml/lib/python3.7/site-packages/tensorflow_core/python/../../_solib_darwin/_U@mkl_Udarwin_S_S_Cmkl_Ulibs_Udarwin___Uexternal_Smkl_Udarwin_Slib/libtensorflow_framework.2.dylib' (no such file), '/Users/cyanaspect/opt/anaconda3/envs/ml/lib/python3.7/site-packages/tensorflow_core/python/libtensorflow_framework.2.dylib' (no such file), '/Users/cyanaspect/opt/anaconda3/envs/ml/lib/python3.7/site-packages/tensorflow_core/python/../libtensorflow_framework.2.dylib' (no such file), '/Users/cyanaspect/opt/anaconda3/envs/ml/lib/python3.7/site-packages/tensorflow_core/python/../../../../libtensorflow_framework.2.dylib' (no such file), '/Users/cyanaspect/opt/anaconda3/envs/ml/bin/../lib/libtensorflow_framework.2.dylib' (no such file), '/Users/cyanaspect/opt/anaconda3/envs/ml/bin/../lib/libtensorflow_framework.2.dylib' (no such file), '/usr/local/lib/libtensorflow_framework.2.dylib' (no such file), '/usr/lib/libtensorflow_framework.2.dylib' (no such file)\n",
      "\n",
      "\n",
      "Failed to load the native TensorFlow runtime.\n",
      "\n",
      "See https://www.tensorflow.org/install/errors\n",
      "\n",
      "for some common reasons and solutions.  Include the entire stack trace\n",
      "above this error message when asking for help.\n"
     ]
    }
   ],
   "source": [
    "clusters_for_each_window[0][4]"
   ]
  },
  {
   "cell_type": "markdown",
   "id": "66a9f74b",
   "metadata": {},
   "source": [
    "# Reclustering \"useless\" articles\n",
    "Findings: Seems like its not useful"
   ]
  },
  {
   "cell_type": "code",
   "execution_count": 256,
   "id": "6c474685",
   "metadata": {
    "scrolled": false
   },
   "outputs": [],
   "source": [
    "model_for_useless_articles = OPTICS(min_samples=2, xi=0.05)\n",
    "useless_articles = clusters_for_each_window[1][0]\n",
    "\n",
    "x = np.stack(useless_articles.embeddings)\n",
    "model_for_useless_articles = model_for_useless_articles.fit(x)\n",
    "clusters = partition_into_clusters(useless_articles, model_for_useless_articles)"
   ]
  },
  {
   "cell_type": "code",
   "execution_count": 257,
   "id": "149c1603",
   "metadata": {},
   "outputs": [
    {
     "name": "stdout",
     "output_type": "stream",
     "text": [
      "ERROR! Session/line number was not unique in database. History logging moved to new session 263\n"
     ]
    },
    {
     "data": {
      "text/plain": [
       "[2]"
      ]
     },
     "execution_count": 257,
     "metadata": {},
     "output_type": "execute_result"
    }
   ],
   "source": [
    "[len(c) for c in clusters]"
   ]
  },
  {
   "cell_type": "code",
   "execution_count": null,
   "id": "f64b603e",
   "metadata": {
    "scrolled": true
   },
   "outputs": [
    {
     "name": "stderr",
     "output_type": "stream",
     "text": [
      "ERROR:root:Internal Python error in the inspect module.\n",
      "Below is the traceback from this internal error.\n",
      "\n",
      "ERROR:root:Internal Python error in the inspect module.\n",
      "Below is the traceback from this internal error.\n",
      "\n",
      "ERROR:root:Internal Python error in the inspect module.\n",
      "Below is the traceback from this internal error.\n",
      "\n"
     ]
    },
    {
     "name": "stdout",
     "output_type": "stream",
     "text": [
      "Traceback (most recent call last):\n",
      "  File \"/Users/cyanaspect/opt/anaconda3/envs/ml/lib/python3.7/site-packages/IPython/core/interactiveshell.py\", line 3457, in run_code\n",
      "    exec(code_obj, self.user_global_ns, self.user_ns)\n",
      "  File \"/var/folders/kg/5sdfljwd58339hwyr4gl3bvh0000gn/T/ipykernel_9521/1295585183.py\", line 1, in <module>\n",
      "    display_series(clusters[5].title)\n",
      "IndexError: list index out of range\n",
      "\n",
      "During handling of the above exception, another exception occurred:\n",
      "\n",
      "Traceback (most recent call last):\n",
      "  File \"/Users/cyanaspect/opt/anaconda3/envs/ml/lib/python3.7/site-packages/IPython/core/interactiveshell.py\", line 2077, in showtraceback\n",
      "    stb = value._render_traceback_()\n",
      "AttributeError: 'IndexError' object has no attribute '_render_traceback_'\n",
      "\n",
      "During handling of the above exception, another exception occurred:\n",
      "\n",
      "Traceback (most recent call last):\n",
      "  File \"/Users/cyanaspect/opt/anaconda3/envs/ml/lib/python3.7/site-packages/tensorflow_core/python/pywrap_tensorflow.py\", line 58, in <module>\n",
      "    from tensorflow.python.pywrap_tensorflow_internal import *\n",
      "  File \"/Users/cyanaspect/opt/anaconda3/envs/ml/lib/python3.7/site-packages/tensorflow_core/python/pywrap_tensorflow_internal.py\", line 28, in <module>\n",
      "    _pywrap_tensorflow_internal = swig_import_helper()\n",
      "  File \"/Users/cyanaspect/opt/anaconda3/envs/ml/lib/python3.7/site-packages/tensorflow_core/python/pywrap_tensorflow_internal.py\", line 24, in swig_import_helper\n",
      "    _mod = imp.load_module('_pywrap_tensorflow_internal', fp, pathname, description)\n",
      "  File \"/Users/cyanaspect/opt/anaconda3/envs/ml/lib/python3.7/imp.py\", line 242, in load_module\n",
      "    return load_dynamic(name, filename, file)\n",
      "  File \"/Users/cyanaspect/opt/anaconda3/envs/ml/lib/python3.7/imp.py\", line 342, in load_dynamic\n",
      "    return _load(spec)\n",
      "ImportError: dlopen(/Users/cyanaspect/opt/anaconda3/envs/ml/lib/python3.7/site-packages/tensorflow_core/python/_pywrap_tensorflow_internal.so, 0x0006): Library not loaded: @rpath/libtensorflow_framework.2.dylib\n",
      "  Referenced from: /Users/cyanaspect/opt/anaconda3/envs/ml/lib/python3.7/site-packages/tensorflow_core/python/_pywrap_tensorflow_internal.so\n",
      "  Reason: tried: '/Users/cyanaspect/opt/anaconda3/envs/ml/lib/python3.7/site-packages/tensorflow_core/python/../../_solib_darwin/_U_S_Stensorflow_Spython_C_Upywrap_Utensorflow_Uinternal.so___Utensorflow/libtensorflow_framework.2.dylib' (no such file), '/Users/cyanaspect/opt/anaconda3/envs/ml/lib/python3.7/site-packages/tensorflow_core/python/../../_solib_darwin/_U@mkl_Udarwin_S_S_Cmkl_Ulibs_Udarwin___Uexternal_Smkl_Udarwin_Slib/libtensorflow_framework.2.dylib' (no such file), '/Users/cyanaspect/opt/anaconda3/envs/ml/lib/python3.7/site-packages/tensorflow_core/python/libtensorflow_framework.2.dylib' (no such file), '/Users/cyanaspect/opt/anaconda3/envs/ml/lib/python3.7/site-packages/tensorflow_core/python/../libtensorflow_framework.2.dylib' (no such file), '/Users/cyanaspect/opt/anaconda3/envs/ml/lib/python3.7/site-packages/tensorflow_core/python/../../../../libtensorflow_framework.2.dylib' (no such file), '/Users/cyanaspect/opt/anaconda3/envs/ml/lib/python3.7/site-packages/tensorflow_core/python/../../_solib_darwin/_U_S_Stensorflow_Spython_C_Upywrap_Utensorflow_Uinternal.so___Utensorflow/libtensorflow_framework.2.dylib' (no such file), '/Users/cyanaspect/opt/anaconda3/envs/ml/lib/python3.7/site-packages/tensorflow_core/python/../../_solib_darwin/_U@mkl_Udarwin_S_S_Cmkl_Ulibs_Udarwin___Uexternal_Smkl_Udarwin_Slib/libtensorflow_framework.2.dylib' (no such file), '/Users/cyanaspect/opt/anaconda3/envs/ml/lib/python3.7/site-packages/tensorflow_core/python/libtensorflow_framework.2.dylib' (no such file), '/Users/cyanaspect/opt/anaconda3/envs/ml/lib/python3.7/site-packages/tensorflow_core/python/../libtensorflow_framework.2.dylib' (no such file), '/Users/cyanaspect/opt/anaconda3/envs/ml/lib/python3.7/site-packages/tensorflow_core/python/../../../../libtensorflow_framework.2.dylib' (no such file), '/Users/cyanaspect/opt/anaconda3/envs/ml/bin/../lib/libtensorflow_framework.2.dylib' (no such file), '/Users/cyanaspect/opt/anaconda3/envs/ml/bin/../lib/libtensorflow_framework.2.dylib' (no such file), '/usr/local/lib/libtensorflow_framework.2.dylib' (no such file), '/usr/lib/libtensorflow_framework.2.dylib' (no such file)\n",
      "\n",
      "During handling of the above exception, another exception occurred:\n",
      "\n",
      "Traceback (most recent call last):\n",
      "  File \"/Users/cyanaspect/opt/anaconda3/envs/ml/lib/python3.7/site-packages/IPython/core/ultratb.py\", line 1101, in get_records\n",
      "    return _fixed_getinnerframes(etb, number_of_lines_of_context, tb_offset)\n",
      "  File \"/Users/cyanaspect/opt/anaconda3/envs/ml/lib/python3.7/site-packages/IPython/core/ultratb.py\", line 248, in wrapped\n",
      "    return f(*args, **kwargs)\n",
      "  File \"/Users/cyanaspect/opt/anaconda3/envs/ml/lib/python3.7/site-packages/IPython/core/ultratb.py\", line 281, in _fixed_getinnerframes\n",
      "    records = fix_frame_records_filenames(inspect.getinnerframes(etb, context))\n",
      "  File \"/Users/cyanaspect/opt/anaconda3/envs/ml/lib/python3.7/inspect.py\", line 1502, in getinnerframes\n",
      "    frameinfo = (tb.tb_frame,) + getframeinfo(tb, context)\n",
      "  File \"/Users/cyanaspect/opt/anaconda3/envs/ml/lib/python3.7/inspect.py\", line 1460, in getframeinfo\n",
      "    filename = getsourcefile(frame) or getfile(frame)\n",
      "  File \"/Users/cyanaspect/opt/anaconda3/envs/ml/lib/python3.7/inspect.py\", line 696, in getsourcefile\n",
      "    if getattr(getmodule(object, filename), '__loader__', None) is not None:\n",
      "  File \"/Users/cyanaspect/opt/anaconda3/envs/ml/lib/python3.7/inspect.py\", line 733, in getmodule\n",
      "    if ismodule(module) and hasattr(module, '__file__'):\n",
      "  File \"/Users/cyanaspect/opt/anaconda3/envs/ml/lib/python3.7/site-packages/tensorflow/__init__.py\", line 50, in __getattr__\n",
      "    module = self._load()\n",
      "  File \"/Users/cyanaspect/opt/anaconda3/envs/ml/lib/python3.7/site-packages/tensorflow/__init__.py\", line 44, in _load\n",
      "    module = _importlib.import_module(self.__name__)\n",
      "  File \"/Users/cyanaspect/opt/anaconda3/envs/ml/lib/python3.7/importlib/__init__.py\", line 127, in import_module\n",
      "    return _bootstrap._gcd_import(name[level:], package, level)\n",
      "  File \"<frozen importlib._bootstrap>\", line 1006, in _gcd_import\n",
      "  File \"<frozen importlib._bootstrap>\", line 983, in _find_and_load\n",
      "  File \"<frozen importlib._bootstrap>\", line 953, in _find_and_load_unlocked\n",
      "  File \"<frozen importlib._bootstrap>\", line 219, in _call_with_frames_removed\n",
      "  File \"<frozen importlib._bootstrap>\", line 1006, in _gcd_import\n",
      "  File \"<frozen importlib._bootstrap>\", line 983, in _find_and_load\n",
      "  File \"<frozen importlib._bootstrap>\", line 967, in _find_and_load_unlocked\n",
      "  File \"<frozen importlib._bootstrap>\", line 677, in _load_unlocked\n",
      "  File \"<frozen importlib._bootstrap_external>\", line 728, in exec_module\n",
      "  File \"<frozen importlib._bootstrap>\", line 219, in _call_with_frames_removed\n",
      "  File \"/Users/cyanaspect/opt/anaconda3/envs/ml/lib/python3.7/site-packages/tensorflow_core/__init__.py\", line 42, in <module>\n",
      "    from . _api.v2 import audio\n",
      "  File \"/Users/cyanaspect/opt/anaconda3/envs/ml/lib/python3.7/site-packages/tensorflow_core/_api/v2/audio/__init__.py\", line 10, in <module>\n",
      "    from tensorflow.python.ops.gen_audio_ops import decode_wav\n",
      "  File \"/Users/cyanaspect/opt/anaconda3/envs/ml/lib/python3.7/site-packages/tensorflow_core/python/ops/gen_audio_ops.py\", line 10, in <module>\n",
      "    from tensorflow.python import pywrap_tensorflow as _pywrap_tensorflow\n",
      "  File \"/Users/cyanaspect/opt/anaconda3/envs/ml/lib/python3.7/site-packages/tensorflow/__init__.py\", line 50, in __getattr__\n",
      "    module = self._load()\n",
      "  File \"/Users/cyanaspect/opt/anaconda3/envs/ml/lib/python3.7/site-packages/tensorflow/__init__.py\", line 44, in _load\n",
      "    module = _importlib.import_module(self.__name__)\n",
      "  File \"/Users/cyanaspect/opt/anaconda3/envs/ml/lib/python3.7/importlib/__init__.py\", line 127, in import_module\n",
      "    return _bootstrap._gcd_import(name[level:], package, level)\n",
      "  File \"/Users/cyanaspect/opt/anaconda3/envs/ml/lib/python3.7/site-packages/tensorflow_core/python/__init__.py\", line 49, in <module>\n",
      "    from tensorflow.python import pywrap_tensorflow\n",
      "  File \"/Users/cyanaspect/opt/anaconda3/envs/ml/lib/python3.7/site-packages/tensorflow_core/python/pywrap_tensorflow.py\", line 74, in <module>\n",
      "    raise ImportError(msg)\n",
      "ImportError: Traceback (most recent call last):\n",
      "  File \"/Users/cyanaspect/opt/anaconda3/envs/ml/lib/python3.7/site-packages/IPython/core/interactiveshell.py\", line 3457, in run_code\n",
      "    exec(code_obj, self.user_global_ns, self.user_ns)\n",
      "  File \"/var/folders/kg/5sdfljwd58339hwyr4gl3bvh0000gn/T/ipykernel_9521/1295585183.py\", line 1, in <module>\n",
      "    display_series(clusters[5].title)\n",
      "IndexError: list index out of range\n",
      "\n",
      "During handling of the above exception, another exception occurred:\n",
      "\n",
      "Traceback (most recent call last):\n",
      "  File \"/Users/cyanaspect/opt/anaconda3/envs/ml/lib/python3.7/site-packages/IPython/core/interactiveshell.py\", line 2077, in showtraceback\n",
      "    stb = value._render_traceback_()\n",
      "AttributeError: 'IndexError' object has no attribute '_render_traceback_'\n",
      "\n",
      "During handling of the above exception, another exception occurred:\n",
      "\n",
      "Traceback (most recent call last):\n",
      "  File \"/Users/cyanaspect/opt/anaconda3/envs/ml/lib/python3.7/site-packages/tensorflow_core/python/pywrap_tensorflow.py\", line 58, in <module>\n",
      "    from tensorflow.python.pywrap_tensorflow_internal import *\n",
      "  File \"/Users/cyanaspect/opt/anaconda3/envs/ml/lib/python3.7/site-packages/tensorflow_core/python/pywrap_tensorflow_internal.py\", line 28, in <module>\n",
      "    _pywrap_tensorflow_internal = swig_import_helper()\n",
      "  File \"/Users/cyanaspect/opt/anaconda3/envs/ml/lib/python3.7/site-packages/tensorflow_core/python/pywrap_tensorflow_internal.py\", line 24, in swig_import_helper\n",
      "    _mod = imp.load_module('_pywrap_tensorflow_internal', fp, pathname, description)\n",
      "  File \"/Users/cyanaspect/opt/anaconda3/envs/ml/lib/python3.7/imp.py\", line 242, in load_module\n",
      "    return load_dynamic(name, filename, file)\n",
      "  File \"/Users/cyanaspect/opt/anaconda3/envs/ml/lib/python3.7/imp.py\", line 342, in load_dynamic\n",
      "    return _load(spec)\n",
      "ImportError: dlopen(/Users/cyanaspect/opt/anaconda3/envs/ml/lib/python3.7/site-packages/tensorflow_core/python/_pywrap_tensorflow_internal.so, 0x0006): Library not loaded: @rpath/libtensorflow_framework.2.dylib\n",
      "  Referenced from: /Users/cyanaspect/opt/anaconda3/envs/ml/lib/python3.7/site-packages/tensorflow_core/python/_pywrap_tensorflow_internal.so\n",
      "  Reason: tried: '/Users/cyanaspect/opt/anaconda3/envs/ml/lib/python3.7/site-packages/tensorflow_core/python/../../_solib_darwin/_U_S_Stensorflow_Spython_C_Upywrap_Utensorflow_Uinternal.so___Utensorflow/libtensorflow_framework.2.dylib' (no such file), '/Users/cyanaspect/opt/anaconda3/envs/ml/lib/python3.7/site-packages/tensorflow_core/python/../../_solib_darwin/_U@mkl_Udarwin_S_S_Cmkl_Ulibs_Udarwin___Uexternal_Smkl_Udarwin_Slib/libtensorflow_framework.2.dylib' (no such file), '/Users/cyanaspect/opt/anaconda3/envs/ml/lib/python3.7/site-packages/tensorflow_core/python/libtensorflow_framework.2.dylib' (no such file), '/Users/cyanaspect/opt/anaconda3/envs/ml/lib/python3.7/site-packages/tensorflow_core/python/../libtensorflow_framework.2.dylib' (no such file), '/Users/cyanaspect/opt/anaconda3/envs/ml/lib/python3.7/site-packages/tensorflow_core/python/../../../../libtensorflow_framework.2.dylib' (no such file), '/Users/cyanaspect/opt/anaconda3/envs/ml/lib/python3.7/site-packages/tensorflow_core/python/../../_solib_darwin/_U_S_Stensorflow_Spython_C_Upywrap_Utensorflow_Uinternal.so___Utensorflow/libtensorflow_framework.2.dylib' (no such file), '/Users/cyanaspect/opt/anaconda3/envs/ml/lib/python3.7/site-packages/tensorflow_core/python/../../_solib_darwin/_U@mkl_Udarwin_S_S_Cmkl_Ulibs_Udarwin___Uexternal_Smkl_Udarwin_Slib/libtensorflow_framework.2.dylib' (no such file), '/Users/cyanaspect/opt/anaconda3/envs/ml/lib/python3.7/site-packages/tensorflow_core/python/libtensorflow_framework.2.dylib' (no such file), '/Users/cyanaspect/opt/anaconda3/envs/ml/lib/python3.7/site-packages/tensorflow_core/python/../libtensorflow_framework.2.dylib' (no such file), '/Users/cyanaspect/opt/anaconda3/envs/ml/lib/python3.7/site-packages/tensorflow_core/python/../../../../libtensorflow_framework.2.dylib' (no such file), '/Users/cyanaspect/opt/anaconda3/envs/ml/bin/../lib/libtensorflow_framework.2.dylib' (no such file), '/Users/cyanaspect/opt/anaconda3/envs/ml/bin/../lib/libtensorflow_framework.2.dylib' (no such file), '/usr/local/lib/libtensorflow_framework.2.dylib' (no such file), '/usr/lib/libtensorflow_framework.2.dylib' (no such file)\n",
      "\n",
      "\n",
      "Failed to load the native TensorFlow runtime.\n",
      "\n",
      "See https://www.tensorflow.org/install/errors\n",
      "\n",
      "for some common reasons and solutions.  Include the entire stack trace\n",
      "above this error message when asking for help.\n",
      "Traceback (most recent call last):\n",
      "  File \"/Users/cyanaspect/opt/anaconda3/envs/ml/lib/python3.7/site-packages/IPython/core/interactiveshell.py\", line 3457, in run_code\n",
      "    exec(code_obj, self.user_global_ns, self.user_ns)\n",
      "  File \"/var/folders/kg/5sdfljwd58339hwyr4gl3bvh0000gn/T/ipykernel_9521/1295585183.py\", line 1, in <module>\n",
      "    display_series(clusters[5].title)\n",
      "IndexError: list index out of range\n",
      "\n",
      "During handling of the above exception, another exception occurred:\n",
      "\n",
      "Traceback (most recent call last):\n",
      "  File \"/Users/cyanaspect/opt/anaconda3/envs/ml/lib/python3.7/site-packages/IPython/core/interactiveshell.py\", line 2077, in showtraceback\n",
      "    stb = value._render_traceback_()\n",
      "AttributeError: 'IndexError' object has no attribute '_render_traceback_'\n",
      "\n",
      "During handling of the above exception, another exception occurred:\n",
      "\n",
      "Traceback (most recent call last):\n",
      "  File \"/Users/cyanaspect/opt/anaconda3/envs/ml/lib/python3.7/site-packages/IPython/core/interactiveshell.py\", line 3377, in run_ast_nodes\n",
      "    if (await self.run_code(code, result,  async_=asy)):\n",
      "  File \"/Users/cyanaspect/opt/anaconda3/envs/ml/lib/python3.7/site-packages/IPython/core/interactiveshell.py\", line 3474, in run_code\n",
      "    self.showtraceback(running_compiled_code=True)\n",
      "  File \"/Users/cyanaspect/opt/anaconda3/envs/ml/lib/python3.7/site-packages/IPython/core/interactiveshell.py\", line 2080, in showtraceback\n",
      "    value, tb, tb_offset=tb_offset)\n",
      "  File \"/Users/cyanaspect/opt/anaconda3/envs/ml/lib/python3.7/site-packages/IPython/core/ultratb.py\", line 1368, in structured_traceback\n",
      "    self, etype, value, tb, tb_offset, number_of_lines_of_context)\n",
      "  File \"/Users/cyanaspect/opt/anaconda3/envs/ml/lib/python3.7/site-packages/IPython/core/ultratb.py\", line 1268, in structured_traceback\n",
      "    self, etype, value, tb, tb_offset, number_of_lines_of_context\n",
      "  File \"/Users/cyanaspect/opt/anaconda3/envs/ml/lib/python3.7/site-packages/IPython/core/ultratb.py\", line 1125, in structured_traceback\n",
      "    tb_offset)\n",
      "  File \"/Users/cyanaspect/opt/anaconda3/envs/ml/lib/python3.7/site-packages/IPython/core/ultratb.py\", line 1082, in format_exception_as_a_whole\n",
      "    last_unique, recursion_repeat = find_recursion(orig_etype, evalue, records)\n",
      "  File \"/Users/cyanaspect/opt/anaconda3/envs/ml/lib/python3.7/site-packages/IPython/core/ultratb.py\", line 382, in find_recursion\n",
      "    return len(records), 0\n",
      "TypeError: object of type 'NoneType' has no len()\n",
      "\n",
      "During handling of the above exception, another exception occurred:\n",
      "\n",
      "Traceback (most recent call last):\n",
      "  File \"/Users/cyanaspect/opt/anaconda3/envs/ml/lib/python3.7/site-packages/IPython/core/interactiveshell.py\", line 2077, in showtraceback\n",
      "    stb = value._render_traceback_()\n",
      "AttributeError: 'TypeError' object has no attribute '_render_traceback_'\n",
      "\n",
      "During handling of the above exception, another exception occurred:\n",
      "\n",
      "Traceback (most recent call last):\n",
      "  File \"/Users/cyanaspect/opt/anaconda3/envs/ml/lib/python3.7/site-packages/tensorflow_core/python/pywrap_tensorflow.py\", line 58, in <module>\n",
      "    from tensorflow.python.pywrap_tensorflow_internal import *\n",
      "  File \"/Users/cyanaspect/opt/anaconda3/envs/ml/lib/python3.7/site-packages/tensorflow_core/python/pywrap_tensorflow_internal.py\", line 28, in <module>\n",
      "    _pywrap_tensorflow_internal = swig_import_helper()\n",
      "  File \"/Users/cyanaspect/opt/anaconda3/envs/ml/lib/python3.7/site-packages/tensorflow_core/python/pywrap_tensorflow_internal.py\", line 24, in swig_import_helper\n",
      "    _mod = imp.load_module('_pywrap_tensorflow_internal', fp, pathname, description)\n",
      "  File \"/Users/cyanaspect/opt/anaconda3/envs/ml/lib/python3.7/imp.py\", line 242, in load_module\n",
      "    return load_dynamic(name, filename, file)\n",
      "  File \"/Users/cyanaspect/opt/anaconda3/envs/ml/lib/python3.7/imp.py\", line 342, in load_dynamic\n",
      "    return _load(spec)\n",
      "ImportError: dlopen(/Users/cyanaspect/opt/anaconda3/envs/ml/lib/python3.7/site-packages/tensorflow_core/python/_pywrap_tensorflow_internal.so, 0x0006): Library not loaded: @rpath/libtensorflow_framework.2.dylib\n",
      "  Referenced from: /Users/cyanaspect/opt/anaconda3/envs/ml/lib/python3.7/site-packages/tensorflow_core/python/_pywrap_tensorflow_internal.so\n",
      "  Reason: tried: '/Users/cyanaspect/opt/anaconda3/envs/ml/lib/python3.7/site-packages/tensorflow_core/python/../../_solib_darwin/_U_S_Stensorflow_Spython_C_Upywrap_Utensorflow_Uinternal.so___Utensorflow/libtensorflow_framework.2.dylib' (no such file), '/Users/cyanaspect/opt/anaconda3/envs/ml/lib/python3.7/site-packages/tensorflow_core/python/../../_solib_darwin/_U@mkl_Udarwin_S_S_Cmkl_Ulibs_Udarwin___Uexternal_Smkl_Udarwin_Slib/libtensorflow_framework.2.dylib' (no such file), '/Users/cyanaspect/opt/anaconda3/envs/ml/lib/python3.7/site-packages/tensorflow_core/python/libtensorflow_framework.2.dylib' (no such file), '/Users/cyanaspect/opt/anaconda3/envs/ml/lib/python3.7/site-packages/tensorflow_core/python/../libtensorflow_framework.2.dylib' (no such file), '/Users/cyanaspect/opt/anaconda3/envs/ml/lib/python3.7/site-packages/tensorflow_core/python/../../../../libtensorflow_framework.2.dylib' (no such file), '/Users/cyanaspect/opt/anaconda3/envs/ml/lib/python3.7/site-packages/tensorflow_core/python/../../_solib_darwin/_U_S_Stensorflow_Spython_C_Upywrap_Utensorflow_Uinternal.so___Utensorflow/libtensorflow_framework.2.dylib' (no such file), '/Users/cyanaspect/opt/anaconda3/envs/ml/lib/python3.7/site-packages/tensorflow_core/python/../../_solib_darwin/_U@mkl_Udarwin_S_S_Cmkl_Ulibs_Udarwin___Uexternal_Smkl_Udarwin_Slib/libtensorflow_framework.2.dylib' (no such file), '/Users/cyanaspect/opt/anaconda3/envs/ml/lib/python3.7/site-packages/tensorflow_core/python/libtensorflow_framework.2.dylib' (no such file), '/Users/cyanaspect/opt/anaconda3/envs/ml/lib/python3.7/site-packages/tensorflow_core/python/../libtensorflow_framework.2.dylib' (no such file), '/Users/cyanaspect/opt/anaconda3/envs/ml/lib/python3.7/site-packages/tensorflow_core/python/../../../../libtensorflow_framework.2.dylib' (no such file), '/Users/cyanaspect/opt/anaconda3/envs/ml/bin/../lib/libtensorflow_framework.2.dylib' (no such file), '/Users/cyanaspect/opt/anaconda3/envs/ml/bin/../lib/libtensorflow_framework.2.dylib' (no such file), '/usr/local/lib/libtensorflow_framework.2.dylib' (no such file), '/usr/lib/libtensorflow_framework.2.dylib' (no such file)\n",
      "\n",
      "During handling of the above exception, another exception occurred:\n",
      "\n",
      "Traceback (most recent call last):\n",
      "  File \"/Users/cyanaspect/opt/anaconda3/envs/ml/lib/python3.7/site-packages/IPython/core/ultratb.py\", line 1101, in get_records\n",
      "    return _fixed_getinnerframes(etb, number_of_lines_of_context, tb_offset)\n",
      "  File \"/Users/cyanaspect/opt/anaconda3/envs/ml/lib/python3.7/site-packages/IPython/core/ultratb.py\", line 248, in wrapped\n",
      "    return f(*args, **kwargs)\n",
      "  File \"/Users/cyanaspect/opt/anaconda3/envs/ml/lib/python3.7/site-packages/IPython/core/ultratb.py\", line 281, in _fixed_getinnerframes\n",
      "    records = fix_frame_records_filenames(inspect.getinnerframes(etb, context))\n",
      "  File \"/Users/cyanaspect/opt/anaconda3/envs/ml/lib/python3.7/inspect.py\", line 1502, in getinnerframes\n",
      "    frameinfo = (tb.tb_frame,) + getframeinfo(tb, context)\n",
      "  File \"/Users/cyanaspect/opt/anaconda3/envs/ml/lib/python3.7/inspect.py\", line 1460, in getframeinfo\n",
      "    filename = getsourcefile(frame) or getfile(frame)\n",
      "  File \"/Users/cyanaspect/opt/anaconda3/envs/ml/lib/python3.7/inspect.py\", line 696, in getsourcefile\n",
      "    if getattr(getmodule(object, filename), '__loader__', None) is not None:\n",
      "  File \"/Users/cyanaspect/opt/anaconda3/envs/ml/lib/python3.7/inspect.py\", line 733, in getmodule\n",
      "    if ismodule(module) and hasattr(module, '__file__'):\n",
      "  File \"/Users/cyanaspect/opt/anaconda3/envs/ml/lib/python3.7/site-packages/tensorflow/__init__.py\", line 50, in __getattr__\n",
      "    module = self._load()\n",
      "  File \"/Users/cyanaspect/opt/anaconda3/envs/ml/lib/python3.7/site-packages/tensorflow/__init__.py\", line 44, in _load\n",
      "    module = _importlib.import_module(self.__name__)\n",
      "  File \"/Users/cyanaspect/opt/anaconda3/envs/ml/lib/python3.7/importlib/__init__.py\", line 127, in import_module\n",
      "    return _bootstrap._gcd_import(name[level:], package, level)\n",
      "  File \"<frozen importlib._bootstrap>\", line 1006, in _gcd_import\n",
      "  File \"<frozen importlib._bootstrap>\", line 983, in _find_and_load\n",
      "  File \"<frozen importlib._bootstrap>\", line 953, in _find_and_load_unlocked\n",
      "  File \"<frozen importlib._bootstrap>\", line 219, in _call_with_frames_removed\n",
      "  File \"<frozen importlib._bootstrap>\", line 1006, in _gcd_import\n",
      "  File \"<frozen importlib._bootstrap>\", line 983, in _find_and_load\n",
      "  File \"<frozen importlib._bootstrap>\", line 967, in _find_and_load_unlocked\n",
      "  File \"<frozen importlib._bootstrap>\", line 677, in _load_unlocked\n",
      "  File \"<frozen importlib._bootstrap_external>\", line 728, in exec_module\n",
      "  File \"<frozen importlib._bootstrap>\", line 219, in _call_with_frames_removed\n",
      "  File \"/Users/cyanaspect/opt/anaconda3/envs/ml/lib/python3.7/site-packages/tensorflow_core/__init__.py\", line 42, in <module>\n",
      "    from . _api.v2 import audio\n",
      "  File \"/Users/cyanaspect/opt/anaconda3/envs/ml/lib/python3.7/site-packages/tensorflow_core/_api/v2/audio/__init__.py\", line 10, in <module>\n",
      "    from tensorflow.python.ops.gen_audio_ops import decode_wav\n",
      "  File \"/Users/cyanaspect/opt/anaconda3/envs/ml/lib/python3.7/site-packages/tensorflow_core/python/ops/gen_audio_ops.py\", line 10, in <module>\n",
      "    from tensorflow.python import pywrap_tensorflow as _pywrap_tensorflow\n",
      "  File \"/Users/cyanaspect/opt/anaconda3/envs/ml/lib/python3.7/site-packages/tensorflow/__init__.py\", line 50, in __getattr__\n",
      "    module = self._load()\n",
      "  File \"/Users/cyanaspect/opt/anaconda3/envs/ml/lib/python3.7/site-packages/tensorflow/__init__.py\", line 44, in _load\n",
      "    module = _importlib.import_module(self.__name__)\n",
      "  File \"/Users/cyanaspect/opt/anaconda3/envs/ml/lib/python3.7/importlib/__init__.py\", line 127, in import_module\n",
      "    return _bootstrap._gcd_import(name[level:], package, level)\n",
      "  File \"/Users/cyanaspect/opt/anaconda3/envs/ml/lib/python3.7/site-packages/tensorflow_core/python/__init__.py\", line 49, in <module>\n",
      "    from tensorflow.python import pywrap_tensorflow\n",
      "  File \"/Users/cyanaspect/opt/anaconda3/envs/ml/lib/python3.7/site-packages/tensorflow_core/python/pywrap_tensorflow.py\", line 74, in <module>\n",
      "    raise ImportError(msg)\n",
      "ImportError: Traceback (most recent call last):\n",
      "  File \"/Users/cyanaspect/opt/anaconda3/envs/ml/lib/python3.7/site-packages/IPython/core/interactiveshell.py\", line 3457, in run_code\n",
      "    exec(code_obj, self.user_global_ns, self.user_ns)\n",
      "  File \"/var/folders/kg/5sdfljwd58339hwyr4gl3bvh0000gn/T/ipykernel_9521/1295585183.py\", line 1, in <module>\n",
      "    display_series(clusters[5].title)\n",
      "IndexError: list index out of range\n",
      "\n",
      "During handling of the above exception, another exception occurred:\n",
      "\n",
      "Traceback (most recent call last):\n",
      "  File \"/Users/cyanaspect/opt/anaconda3/envs/ml/lib/python3.7/site-packages/IPython/core/interactiveshell.py\", line 2077, in showtraceback\n",
      "    stb = value._render_traceback_()\n",
      "AttributeError: 'IndexError' object has no attribute '_render_traceback_'\n",
      "\n",
      "During handling of the above exception, another exception occurred:\n",
      "\n",
      "Traceback (most recent call last):\n",
      "  File \"/Users/cyanaspect/opt/anaconda3/envs/ml/lib/python3.7/site-packages/IPython/core/interactiveshell.py\", line 3377, in run_ast_nodes\n",
      "    if (await self.run_code(code, result,  async_=asy)):\n",
      "  File \"/Users/cyanaspect/opt/anaconda3/envs/ml/lib/python3.7/site-packages/IPython/core/interactiveshell.py\", line 3474, in run_code\n",
      "    self.showtraceback(running_compiled_code=True)\n",
      "  File \"/Users/cyanaspect/opt/anaconda3/envs/ml/lib/python3.7/site-packages/IPython/core/interactiveshell.py\", line 2080, in showtraceback\n",
      "    value, tb, tb_offset=tb_offset)\n",
      "  File \"/Users/cyanaspect/opt/anaconda3/envs/ml/lib/python3.7/site-packages/IPython/core/ultratb.py\", line 1368, in structured_traceback\n",
      "    self, etype, value, tb, tb_offset, number_of_lines_of_context)\n",
      "  File \"/Users/cyanaspect/opt/anaconda3/envs/ml/lib/python3.7/site-packages/IPython/core/ultratb.py\", line 1268, in structured_traceback\n",
      "    self, etype, value, tb, tb_offset, number_of_lines_of_context\n",
      "  File \"/Users/cyanaspect/opt/anaconda3/envs/ml/lib/python3.7/site-packages/IPython/core/ultratb.py\", line 1125, in structured_traceback\n",
      "    tb_offset)\n",
      "  File \"/Users/cyanaspect/opt/anaconda3/envs/ml/lib/python3.7/site-packages/IPython/core/ultratb.py\", line 1082, in format_exception_as_a_whole\n",
      "    last_unique, recursion_repeat = find_recursion(orig_etype, evalue, records)\n",
      "  File \"/Users/cyanaspect/opt/anaconda3/envs/ml/lib/python3.7/site-packages/IPython/core/ultratb.py\", line 382, in find_recursion\n",
      "    return len(records), 0\n",
      "TypeError: object of type 'NoneType' has no len()\n",
      "\n",
      "During handling of the above exception, another exception occurred:\n",
      "\n",
      "Traceback (most recent call last):\n",
      "  File \"/Users/cyanaspect/opt/anaconda3/envs/ml/lib/python3.7/site-packages/IPython/core/interactiveshell.py\", line 2077, in showtraceback\n",
      "    stb = value._render_traceback_()\n",
      "AttributeError: 'TypeError' object has no attribute '_render_traceback_'\n",
      "\n",
      "During handling of the above exception, another exception occurred:\n",
      "\n",
      "Traceback (most recent call last):\n",
      "  File \"/Users/cyanaspect/opt/anaconda3/envs/ml/lib/python3.7/site-packages/tensorflow_core/python/pywrap_tensorflow.py\", line 58, in <module>\n",
      "    from tensorflow.python.pywrap_tensorflow_internal import *\n",
      "  File \"/Users/cyanaspect/opt/anaconda3/envs/ml/lib/python3.7/site-packages/tensorflow_core/python/pywrap_tensorflow_internal.py\", line 28, in <module>\n",
      "    _pywrap_tensorflow_internal = swig_import_helper()\n",
      "  File \"/Users/cyanaspect/opt/anaconda3/envs/ml/lib/python3.7/site-packages/tensorflow_core/python/pywrap_tensorflow_internal.py\", line 24, in swig_import_helper\n",
      "    _mod = imp.load_module('_pywrap_tensorflow_internal', fp, pathname, description)\n",
      "  File \"/Users/cyanaspect/opt/anaconda3/envs/ml/lib/python3.7/imp.py\", line 242, in load_module\n",
      "    return load_dynamic(name, filename, file)\n",
      "  File \"/Users/cyanaspect/opt/anaconda3/envs/ml/lib/python3.7/imp.py\", line 342, in load_dynamic\n",
      "    return _load(spec)\n",
      "ImportError: dlopen(/Users/cyanaspect/opt/anaconda3/envs/ml/lib/python3.7/site-packages/tensorflow_core/python/_pywrap_tensorflow_internal.so, 0x0006): Library not loaded: @rpath/libtensorflow_framework.2.dylib\n",
      "  Referenced from: /Users/cyanaspect/opt/anaconda3/envs/ml/lib/python3.7/site-packages/tensorflow_core/python/_pywrap_tensorflow_internal.so\n",
      "  Reason: tried: '/Users/cyanaspect/opt/anaconda3/envs/ml/lib/python3.7/site-packages/tensorflow_core/python/../../_solib_darwin/_U_S_Stensorflow_Spython_C_Upywrap_Utensorflow_Uinternal.so___Utensorflow/libtensorflow_framework.2.dylib' (no such file), '/Users/cyanaspect/opt/anaconda3/envs/ml/lib/python3.7/site-packages/tensorflow_core/python/../../_solib_darwin/_U@mkl_Udarwin_S_S_Cmkl_Ulibs_Udarwin___Uexternal_Smkl_Udarwin_Slib/libtensorflow_framework.2.dylib' (no such file), '/Users/cyanaspect/opt/anaconda3/envs/ml/lib/python3.7/site-packages/tensorflow_core/python/libtensorflow_framework.2.dylib' (no such file), '/Users/cyanaspect/opt/anaconda3/envs/ml/lib/python3.7/site-packages/tensorflow_core/python/../libtensorflow_framework.2.dylib' (no such file), '/Users/cyanaspect/opt/anaconda3/envs/ml/lib/python3.7/site-packages/tensorflow_core/python/../../../../libtensorflow_framework.2.dylib' (no such file), '/Users/cyanaspect/opt/anaconda3/envs/ml/lib/python3.7/site-packages/tensorflow_core/python/../../_solib_darwin/_U_S_Stensorflow_Spython_C_Upywrap_Utensorflow_Uinternal.so___Utensorflow/libtensorflow_framework.2.dylib' (no such file), '/Users/cyanaspect/opt/anaconda3/envs/ml/lib/python3.7/site-packages/tensorflow_core/python/../../_solib_darwin/_U@mkl_Udarwin_S_S_Cmkl_Ulibs_Udarwin___Uexternal_Smkl_Udarwin_Slib/libtensorflow_framework.2.dylib' (no such file), '/Users/cyanaspect/opt/anaconda3/envs/ml/lib/python3.7/site-packages/tensorflow_core/python/libtensorflow_framework.2.dylib' (no such file), '/Users/cyanaspect/opt/anaconda3/envs/ml/lib/python3.7/site-packages/tensorflow_core/python/../libtensorflow_framework.2.dylib' (no such file), '/Users/cyanaspect/opt/anaconda3/envs/ml/lib/python3.7/site-packages/tensorflow_core/python/../../../../libtensorflow_framework.2.dylib' (no such file), '/Users/cyanaspect/opt/anaconda3/envs/ml/bin/../lib/libtensorflow_framework.2.dylib' (no such file), '/Users/cyanaspect/opt/anaconda3/envs/ml/bin/../lib/libtensorflow_framework.2.dylib' (no such file), '/usr/local/lib/libtensorflow_framework.2.dylib' (no such file), '/usr/lib/libtensorflow_framework.2.dylib' (no such file)\n",
      "\n",
      "\n",
      "Failed to load the native TensorFlow runtime.\n",
      "\n",
      "See https://www.tensorflow.org/install/errors\n",
      "\n",
      "for some common reasons and solutions.  Include the entire stack trace\n",
      "above this error message when asking for help.\n",
      "Traceback (most recent call last):\n",
      "  File \"/Users/cyanaspect/opt/anaconda3/envs/ml/lib/python3.7/site-packages/IPython/core/interactiveshell.py\", line 3457, in run_code\n",
      "    exec(code_obj, self.user_global_ns, self.user_ns)\n",
      "  File \"/var/folders/kg/5sdfljwd58339hwyr4gl3bvh0000gn/T/ipykernel_9521/1295585183.py\", line 1, in <module>\n",
      "    display_series(clusters[5].title)\n",
      "IndexError: list index out of range\n",
      "\n",
      "During handling of the above exception, another exception occurred:\n",
      "\n",
      "Traceback (most recent call last):\n",
      "  File \"/Users/cyanaspect/opt/anaconda3/envs/ml/lib/python3.7/site-packages/IPython/core/interactiveshell.py\", line 2077, in showtraceback\n",
      "    stb = value._render_traceback_()\n",
      "AttributeError: 'IndexError' object has no attribute '_render_traceback_'\n",
      "\n",
      "During handling of the above exception, another exception occurred:\n",
      "\n",
      "Traceback (most recent call last):\n",
      "  File \"/Users/cyanaspect/opt/anaconda3/envs/ml/lib/python3.7/site-packages/IPython/core/interactiveshell.py\", line 3377, in run_ast_nodes\n",
      "    if (await self.run_code(code, result,  async_=asy)):\n",
      "  File \"/Users/cyanaspect/opt/anaconda3/envs/ml/lib/python3.7/site-packages/IPython/core/interactiveshell.py\", line 3474, in run_code\n",
      "    self.showtraceback(running_compiled_code=True)\n",
      "  File \"/Users/cyanaspect/opt/anaconda3/envs/ml/lib/python3.7/site-packages/IPython/core/interactiveshell.py\", line 2080, in showtraceback\n",
      "    value, tb, tb_offset=tb_offset)\n",
      "  File \"/Users/cyanaspect/opt/anaconda3/envs/ml/lib/python3.7/site-packages/IPython/core/ultratb.py\", line 1368, in structured_traceback\n",
      "    self, etype, value, tb, tb_offset, number_of_lines_of_context)\n",
      "  File \"/Users/cyanaspect/opt/anaconda3/envs/ml/lib/python3.7/site-packages/IPython/core/ultratb.py\", line 1268, in structured_traceback\n",
      "    self, etype, value, tb, tb_offset, number_of_lines_of_context\n",
      "  File \"/Users/cyanaspect/opt/anaconda3/envs/ml/lib/python3.7/site-packages/IPython/core/ultratb.py\", line 1125, in structured_traceback\n",
      "    tb_offset)\n",
      "  File \"/Users/cyanaspect/opt/anaconda3/envs/ml/lib/python3.7/site-packages/IPython/core/ultratb.py\", line 1082, in format_exception_as_a_whole\n",
      "    last_unique, recursion_repeat = find_recursion(orig_etype, evalue, records)\n",
      "  File \"/Users/cyanaspect/opt/anaconda3/envs/ml/lib/python3.7/site-packages/IPython/core/ultratb.py\", line 382, in find_recursion\n",
      "    return len(records), 0\n",
      "TypeError: object of type 'NoneType' has no len()\n",
      "\n",
      "During handling of the above exception, another exception occurred:\n",
      "\n",
      "Traceback (most recent call last):\n",
      "  File \"/Users/cyanaspect/opt/anaconda3/envs/ml/lib/python3.7/site-packages/IPython/core/interactiveshell.py\", line 2077, in showtraceback\n",
      "    stb = value._render_traceback_()\n",
      "AttributeError: 'TypeError' object has no attribute '_render_traceback_'\n",
      "\n",
      "During handling of the above exception, another exception occurred:\n",
      "\n",
      "Traceback (most recent call last):\n",
      "  File \"/Users/cyanaspect/opt/anaconda3/envs/ml/lib/python3.7/site-packages/IPython/core/interactiveshell.py\", line 2960, in _run_cell\n",
      "    return runner(coro)\n",
      "  File \"/Users/cyanaspect/opt/anaconda3/envs/ml/lib/python3.7/site-packages/IPython/core/async_helpers.py\", line 78, in _pseudo_sync_runner\n",
      "    coro.send(None)\n",
      "  File \"/Users/cyanaspect/opt/anaconda3/envs/ml/lib/python3.7/site-packages/IPython/core/interactiveshell.py\", line 3186, in run_cell_async\n",
      "    interactivity=interactivity, compiler=compiler, result=result)\n",
      "  File \"/Users/cyanaspect/opt/anaconda3/envs/ml/lib/python3.7/site-packages/IPython/core/interactiveshell.py\", line 3396, in run_ast_nodes\n",
      "    self.showtraceback()\n",
      "  File \"/Users/cyanaspect/opt/anaconda3/envs/ml/lib/python3.7/site-packages/IPython/core/interactiveshell.py\", line 2080, in showtraceback\n",
      "    value, tb, tb_offset=tb_offset)\n",
      "  File \"/Users/cyanaspect/opt/anaconda3/envs/ml/lib/python3.7/site-packages/IPython/core/ultratb.py\", line 1368, in structured_traceback\n",
      "    self, etype, value, tb, tb_offset, number_of_lines_of_context)\n",
      "  File \"/Users/cyanaspect/opt/anaconda3/envs/ml/lib/python3.7/site-packages/IPython/core/ultratb.py\", line 1268, in structured_traceback\n",
      "    self, etype, value, tb, tb_offset, number_of_lines_of_context\n",
      "  File \"/Users/cyanaspect/opt/anaconda3/envs/ml/lib/python3.7/site-packages/IPython/core/ultratb.py\", line 1143, in structured_traceback\n",
      "    chained_exceptions_tb_offset)\n",
      "  File \"/Users/cyanaspect/opt/anaconda3/envs/ml/lib/python3.7/site-packages/IPython/core/ultratb.py\", line 1082, in format_exception_as_a_whole\n",
      "    last_unique, recursion_repeat = find_recursion(orig_etype, evalue, records)\n",
      "  File \"/Users/cyanaspect/opt/anaconda3/envs/ml/lib/python3.7/site-packages/IPython/core/ultratb.py\", line 382, in find_recursion\n",
      "    return len(records), 0\n",
      "TypeError: object of type 'NoneType' has no len()\n",
      "\n",
      "During handling of the above exception, another exception occurred:\n",
      "\n",
      "Traceback (most recent call last):\n",
      "  File \"/Users/cyanaspect/opt/anaconda3/envs/ml/lib/python3.7/site-packages/IPython/core/interactiveshell.py\", line 2077, in showtraceback\n",
      "    stb = value._render_traceback_()\n",
      "AttributeError: 'TypeError' object has no attribute '_render_traceback_'\n",
      "\n",
      "During handling of the above exception, another exception occurred:\n",
      "\n",
      "Traceback (most recent call last):\n",
      "  File \"/Users/cyanaspect/opt/anaconda3/envs/ml/lib/python3.7/site-packages/tensorflow_core/python/pywrap_tensorflow.py\", line 58, in <module>\n",
      "    from tensorflow.python.pywrap_tensorflow_internal import *\n",
      "  File \"/Users/cyanaspect/opt/anaconda3/envs/ml/lib/python3.7/site-packages/tensorflow_core/python/pywrap_tensorflow_internal.py\", line 28, in <module>\n",
      "    _pywrap_tensorflow_internal = swig_import_helper()\n",
      "  File \"/Users/cyanaspect/opt/anaconda3/envs/ml/lib/python3.7/site-packages/tensorflow_core/python/pywrap_tensorflow_internal.py\", line 24, in swig_import_helper\n",
      "    _mod = imp.load_module('_pywrap_tensorflow_internal', fp, pathname, description)\n",
      "  File \"/Users/cyanaspect/opt/anaconda3/envs/ml/lib/python3.7/imp.py\", line 242, in load_module\n",
      "    return load_dynamic(name, filename, file)\n",
      "  File \"/Users/cyanaspect/opt/anaconda3/envs/ml/lib/python3.7/imp.py\", line 342, in load_dynamic\n",
      "    return _load(spec)\n",
      "ImportError: dlopen(/Users/cyanaspect/opt/anaconda3/envs/ml/lib/python3.7/site-packages/tensorflow_core/python/_pywrap_tensorflow_internal.so, 0x0006): Library not loaded: @rpath/libtensorflow_framework.2.dylib\n",
      "  Referenced from: /Users/cyanaspect/opt/anaconda3/envs/ml/lib/python3.7/site-packages/tensorflow_core/python/_pywrap_tensorflow_internal.so\n",
      "  Reason: tried: '/Users/cyanaspect/opt/anaconda3/envs/ml/lib/python3.7/site-packages/tensorflow_core/python/../../_solib_darwin/_U_S_Stensorflow_Spython_C_Upywrap_Utensorflow_Uinternal.so___Utensorflow/libtensorflow_framework.2.dylib' (no such file), '/Users/cyanaspect/opt/anaconda3/envs/ml/lib/python3.7/site-packages/tensorflow_core/python/../../_solib_darwin/_U@mkl_Udarwin_S_S_Cmkl_Ulibs_Udarwin___Uexternal_Smkl_Udarwin_Slib/libtensorflow_framework.2.dylib' (no such file), '/Users/cyanaspect/opt/anaconda3/envs/ml/lib/python3.7/site-packages/tensorflow_core/python/libtensorflow_framework.2.dylib' (no such file), '/Users/cyanaspect/opt/anaconda3/envs/ml/lib/python3.7/site-packages/tensorflow_core/python/../libtensorflow_framework.2.dylib' (no such file), '/Users/cyanaspect/opt/anaconda3/envs/ml/lib/python3.7/site-packages/tensorflow_core/python/../../../../libtensorflow_framework.2.dylib' (no such file), '/Users/cyanaspect/opt/anaconda3/envs/ml/lib/python3.7/site-packages/tensorflow_core/python/../../_solib_darwin/_U_S_Stensorflow_Spython_C_Upywrap_Utensorflow_Uinternal.so___Utensorflow/libtensorflow_framework.2.dylib' (no such file), '/Users/cyanaspect/opt/anaconda3/envs/ml/lib/python3.7/site-packages/tensorflow_core/python/../../_solib_darwin/_U@mkl_Udarwin_S_S_Cmkl_Ulibs_Udarwin___Uexternal_Smkl_Udarwin_Slib/libtensorflow_framework.2.dylib' (no such file), '/Users/cyanaspect/opt/anaconda3/envs/ml/lib/python3.7/site-packages/tensorflow_core/python/libtensorflow_framework.2.dylib' (no such file), '/Users/cyanaspect/opt/anaconda3/envs/ml/lib/python3.7/site-packages/tensorflow_core/python/../libtensorflow_framework.2.dylib' (no such file), '/Users/cyanaspect/opt/anaconda3/envs/ml/lib/python3.7/site-packages/tensorflow_core/python/../../../../libtensorflow_framework.2.dylib' (no such file), '/Users/cyanaspect/opt/anaconda3/envs/ml/bin/../lib/libtensorflow_framework.2.dylib' (no such file), '/Users/cyanaspect/opt/anaconda3/envs/ml/bin/../lib/libtensorflow_framework.2.dylib' (no such file), '/usr/local/lib/libtensorflow_framework.2.dylib' (no such file), '/usr/lib/libtensorflow_framework.2.dylib' (no such file)\n",
      "\n",
      "During handling of the above exception, another exception occurred:\n",
      "\n",
      "Traceback (most recent call last):\n",
      "  File \"/Users/cyanaspect/opt/anaconda3/envs/ml/lib/python3.7/site-packages/IPython/core/ultratb.py\", line 1101, in get_records\n",
      "    return _fixed_getinnerframes(etb, number_of_lines_of_context, tb_offset)\n",
      "  File \"/Users/cyanaspect/opt/anaconda3/envs/ml/lib/python3.7/site-packages/IPython/core/ultratb.py\", line 248, in wrapped\n",
      "    return f(*args, **kwargs)\n",
      "  File \"/Users/cyanaspect/opt/anaconda3/envs/ml/lib/python3.7/site-packages/IPython/core/ultratb.py\", line 281, in _fixed_getinnerframes\n",
      "    records = fix_frame_records_filenames(inspect.getinnerframes(etb, context))\n",
      "  File \"/Users/cyanaspect/opt/anaconda3/envs/ml/lib/python3.7/inspect.py\", line 1502, in getinnerframes\n",
      "    frameinfo = (tb.tb_frame,) + getframeinfo(tb, context)\n",
      "  File \"/Users/cyanaspect/opt/anaconda3/envs/ml/lib/python3.7/inspect.py\", line 1460, in getframeinfo\n",
      "    filename = getsourcefile(frame) or getfile(frame)\n",
      "  File \"/Users/cyanaspect/opt/anaconda3/envs/ml/lib/python3.7/inspect.py\", line 696, in getsourcefile\n",
      "    if getattr(getmodule(object, filename), '__loader__', None) is not None:\n",
      "  File \"/Users/cyanaspect/opt/anaconda3/envs/ml/lib/python3.7/inspect.py\", line 733, in getmodule\n",
      "    if ismodule(module) and hasattr(module, '__file__'):\n",
      "  File \"/Users/cyanaspect/opt/anaconda3/envs/ml/lib/python3.7/site-packages/tensorflow/__init__.py\", line 50, in __getattr__\n",
      "    module = self._load()\n",
      "  File \"/Users/cyanaspect/opt/anaconda3/envs/ml/lib/python3.7/site-packages/tensorflow/__init__.py\", line 44, in _load\n",
      "    module = _importlib.import_module(self.__name__)\n",
      "  File \"/Users/cyanaspect/opt/anaconda3/envs/ml/lib/python3.7/importlib/__init__.py\", line 127, in import_module\n",
      "    return _bootstrap._gcd_import(name[level:], package, level)\n",
      "  File \"<frozen importlib._bootstrap>\", line 1006, in _gcd_import\n",
      "  File \"<frozen importlib._bootstrap>\", line 983, in _find_and_load\n",
      "  File \"<frozen importlib._bootstrap>\", line 953, in _find_and_load_unlocked\n",
      "  File \"<frozen importlib._bootstrap>\", line 219, in _call_with_frames_removed\n",
      "  File \"<frozen importlib._bootstrap>\", line 1006, in _gcd_import\n",
      "  File \"<frozen importlib._bootstrap>\", line 983, in _find_and_load\n",
      "  File \"<frozen importlib._bootstrap>\", line 967, in _find_and_load_unlocked\n",
      "  File \"<frozen importlib._bootstrap>\", line 677, in _load_unlocked\n",
      "  File \"<frozen importlib._bootstrap_external>\", line 728, in exec_module\n",
      "  File \"<frozen importlib._bootstrap>\", line 219, in _call_with_frames_removed\n",
      "  File \"/Users/cyanaspect/opt/anaconda3/envs/ml/lib/python3.7/site-packages/tensorflow_core/__init__.py\", line 42, in <module>\n",
      "    from . _api.v2 import audio\n",
      "  File \"/Users/cyanaspect/opt/anaconda3/envs/ml/lib/python3.7/site-packages/tensorflow_core/_api/v2/audio/__init__.py\", line 10, in <module>\n",
      "    from tensorflow.python.ops.gen_audio_ops import decode_wav\n",
      "  File \"/Users/cyanaspect/opt/anaconda3/envs/ml/lib/python3.7/site-packages/tensorflow_core/python/ops/gen_audio_ops.py\", line 10, in <module>\n",
      "    from tensorflow.python import pywrap_tensorflow as _pywrap_tensorflow\n",
      "  File \"/Users/cyanaspect/opt/anaconda3/envs/ml/lib/python3.7/site-packages/tensorflow/__init__.py\", line 50, in __getattr__\n",
      "    module = self._load()\n",
      "  File \"/Users/cyanaspect/opt/anaconda3/envs/ml/lib/python3.7/site-packages/tensorflow/__init__.py\", line 44, in _load\n",
      "    module = _importlib.import_module(self.__name__)\n",
      "  File \"/Users/cyanaspect/opt/anaconda3/envs/ml/lib/python3.7/importlib/__init__.py\", line 127, in import_module\n",
      "    return _bootstrap._gcd_import(name[level:], package, level)\n",
      "  File \"/Users/cyanaspect/opt/anaconda3/envs/ml/lib/python3.7/site-packages/tensorflow_core/python/__init__.py\", line 49, in <module>\n",
      "    from tensorflow.python import pywrap_tensorflow\n",
      "  File \"/Users/cyanaspect/opt/anaconda3/envs/ml/lib/python3.7/site-packages/tensorflow_core/python/pywrap_tensorflow.py\", line 74, in <module>\n",
      "    raise ImportError(msg)\n",
      "ImportError: Traceback (most recent call last):\n",
      "  File \"/Users/cyanaspect/opt/anaconda3/envs/ml/lib/python3.7/site-packages/IPython/core/interactiveshell.py\", line 3457, in run_code\n",
      "    exec(code_obj, self.user_global_ns, self.user_ns)\n",
      "  File \"/var/folders/kg/5sdfljwd58339hwyr4gl3bvh0000gn/T/ipykernel_9521/1295585183.py\", line 1, in <module>\n",
      "    display_series(clusters[5].title)\n",
      "IndexError: list index out of range\n",
      "\n",
      "During handling of the above exception, another exception occurred:\n",
      "\n",
      "Traceback (most recent call last):\n",
      "  File \"/Users/cyanaspect/opt/anaconda3/envs/ml/lib/python3.7/site-packages/IPython/core/interactiveshell.py\", line 2077, in showtraceback\n",
      "    stb = value._render_traceback_()\n",
      "AttributeError: 'IndexError' object has no attribute '_render_traceback_'\n",
      "\n",
      "During handling of the above exception, another exception occurred:\n",
      "\n",
      "Traceback (most recent call last):\n",
      "  File \"/Users/cyanaspect/opt/anaconda3/envs/ml/lib/python3.7/site-packages/IPython/core/interactiveshell.py\", line 3377, in run_ast_nodes\n",
      "    if (await self.run_code(code, result,  async_=asy)):\n",
      "  File \"/Users/cyanaspect/opt/anaconda3/envs/ml/lib/python3.7/site-packages/IPython/core/interactiveshell.py\", line 3474, in run_code\n",
      "    self.showtraceback(running_compiled_code=True)\n",
      "  File \"/Users/cyanaspect/opt/anaconda3/envs/ml/lib/python3.7/site-packages/IPython/core/interactiveshell.py\", line 2080, in showtraceback\n",
      "    value, tb, tb_offset=tb_offset)\n",
      "  File \"/Users/cyanaspect/opt/anaconda3/envs/ml/lib/python3.7/site-packages/IPython/core/ultratb.py\", line 1368, in structured_traceback\n",
      "    self, etype, value, tb, tb_offset, number_of_lines_of_context)\n",
      "  File \"/Users/cyanaspect/opt/anaconda3/envs/ml/lib/python3.7/site-packages/IPython/core/ultratb.py\", line 1268, in structured_traceback\n",
      "    self, etype, value, tb, tb_offset, number_of_lines_of_context\n",
      "  File \"/Users/cyanaspect/opt/anaconda3/envs/ml/lib/python3.7/site-packages/IPython/core/ultratb.py\", line 1125, in structured_traceback\n",
      "    tb_offset)\n",
      "  File \"/Users/cyanaspect/opt/anaconda3/envs/ml/lib/python3.7/site-packages/IPython/core/ultratb.py\", line 1082, in format_exception_as_a_whole\n",
      "    last_unique, recursion_repeat = find_recursion(orig_etype, evalue, records)\n",
      "  File \"/Users/cyanaspect/opt/anaconda3/envs/ml/lib/python3.7/site-packages/IPython/core/ultratb.py\", line 382, in find_recursion\n",
      "    return len(records), 0\n",
      "TypeError: object of type 'NoneType' has no len()\n",
      "\n",
      "During handling of the above exception, another exception occurred:\n",
      "\n",
      "Traceback (most recent call last):\n",
      "  File \"/Users/cyanaspect/opt/anaconda3/envs/ml/lib/python3.7/site-packages/IPython/core/interactiveshell.py\", line 2077, in showtraceback\n",
      "    stb = value._render_traceback_()\n",
      "AttributeError: 'TypeError' object has no attribute '_render_traceback_'\n",
      "\n",
      "During handling of the above exception, another exception occurred:\n",
      "\n",
      "Traceback (most recent call last):\n",
      "  File \"/Users/cyanaspect/opt/anaconda3/envs/ml/lib/python3.7/site-packages/IPython/core/interactiveshell.py\", line 2960, in _run_cell\n",
      "    return runner(coro)\n",
      "  File \"/Users/cyanaspect/opt/anaconda3/envs/ml/lib/python3.7/site-packages/IPython/core/async_helpers.py\", line 78, in _pseudo_sync_runner\n",
      "    coro.send(None)\n",
      "  File \"/Users/cyanaspect/opt/anaconda3/envs/ml/lib/python3.7/site-packages/IPython/core/interactiveshell.py\", line 3186, in run_cell_async\n",
      "    interactivity=interactivity, compiler=compiler, result=result)\n",
      "  File \"/Users/cyanaspect/opt/anaconda3/envs/ml/lib/python3.7/site-packages/IPython/core/interactiveshell.py\", line 3396, in run_ast_nodes\n",
      "    self.showtraceback()\n",
      "  File \"/Users/cyanaspect/opt/anaconda3/envs/ml/lib/python3.7/site-packages/IPython/core/interactiveshell.py\", line 2080, in showtraceback\n",
      "    value, tb, tb_offset=tb_offset)\n",
      "  File \"/Users/cyanaspect/opt/anaconda3/envs/ml/lib/python3.7/site-packages/IPython/core/ultratb.py\", line 1368, in structured_traceback\n",
      "    self, etype, value, tb, tb_offset, number_of_lines_of_context)\n",
      "  File \"/Users/cyanaspect/opt/anaconda3/envs/ml/lib/python3.7/site-packages/IPython/core/ultratb.py\", line 1268, in structured_traceback\n",
      "    self, etype, value, tb, tb_offset, number_of_lines_of_context\n",
      "  File \"/Users/cyanaspect/opt/anaconda3/envs/ml/lib/python3.7/site-packages/IPython/core/ultratb.py\", line 1143, in structured_traceback\n",
      "    chained_exceptions_tb_offset)\n",
      "  File \"/Users/cyanaspect/opt/anaconda3/envs/ml/lib/python3.7/site-packages/IPython/core/ultratb.py\", line 1082, in format_exception_as_a_whole\n",
      "    last_unique, recursion_repeat = find_recursion(orig_etype, evalue, records)\n",
      "  File \"/Users/cyanaspect/opt/anaconda3/envs/ml/lib/python3.7/site-packages/IPython/core/ultratb.py\", line 382, in find_recursion\n",
      "    return len(records), 0\n",
      "TypeError: object of type 'NoneType' has no len()\n",
      "\n",
      "During handling of the above exception, another exception occurred:\n",
      "\n",
      "Traceback (most recent call last):\n",
      "  File \"/Users/cyanaspect/opt/anaconda3/envs/ml/lib/python3.7/site-packages/IPython/core/interactiveshell.py\", line 2077, in showtraceback\n",
      "    stb = value._render_traceback_()\n",
      "AttributeError: 'TypeError' object has no attribute '_render_traceback_'\n",
      "\n",
      "During handling of the above exception, another exception occurred:\n",
      "\n",
      "Traceback (most recent call last):\n",
      "  File \"/Users/cyanaspect/opt/anaconda3/envs/ml/lib/python3.7/site-packages/tensorflow_core/python/pywrap_tensorflow.py\", line 58, in <module>\n",
      "    from tensorflow.python.pywrap_tensorflow_internal import *\n",
      "  File \"/Users/cyanaspect/opt/anaconda3/envs/ml/lib/python3.7/site-packages/tensorflow_core/python/pywrap_tensorflow_internal.py\", line 28, in <module>\n",
      "    _pywrap_tensorflow_internal = swig_import_helper()\n",
      "  File \"/Users/cyanaspect/opt/anaconda3/envs/ml/lib/python3.7/site-packages/tensorflow_core/python/pywrap_tensorflow_internal.py\", line 24, in swig_import_helper\n",
      "    _mod = imp.load_module('_pywrap_tensorflow_internal', fp, pathname, description)\n",
      "  File \"/Users/cyanaspect/opt/anaconda3/envs/ml/lib/python3.7/imp.py\", line 242, in load_module\n",
      "    return load_dynamic(name, filename, file)\n",
      "  File \"/Users/cyanaspect/opt/anaconda3/envs/ml/lib/python3.7/imp.py\", line 342, in load_dynamic\n",
      "    return _load(spec)\n",
      "ImportError: dlopen(/Users/cyanaspect/opt/anaconda3/envs/ml/lib/python3.7/site-packages/tensorflow_core/python/_pywrap_tensorflow_internal.so, 0x0006): Library not loaded: @rpath/libtensorflow_framework.2.dylib\n",
      "  Referenced from: /Users/cyanaspect/opt/anaconda3/envs/ml/lib/python3.7/site-packages/tensorflow_core/python/_pywrap_tensorflow_internal.so\n",
      "  Reason: tried: '/Users/cyanaspect/opt/anaconda3/envs/ml/lib/python3.7/site-packages/tensorflow_core/python/../../_solib_darwin/_U_S_Stensorflow_Spython_C_Upywrap_Utensorflow_Uinternal.so___Utensorflow/libtensorflow_framework.2.dylib' (no such file), '/Users/cyanaspect/opt/anaconda3/envs/ml/lib/python3.7/site-packages/tensorflow_core/python/../../_solib_darwin/_U@mkl_Udarwin_S_S_Cmkl_Ulibs_Udarwin___Uexternal_Smkl_Udarwin_Slib/libtensorflow_framework.2.dylib' (no such file), '/Users/cyanaspect/opt/anaconda3/envs/ml/lib/python3.7/site-packages/tensorflow_core/python/libtensorflow_framework.2.dylib' (no such file), '/Users/cyanaspect/opt/anaconda3/envs/ml/lib/python3.7/site-packages/tensorflow_core/python/../libtensorflow_framework.2.dylib' (no such file), '/Users/cyanaspect/opt/anaconda3/envs/ml/lib/python3.7/site-packages/tensorflow_core/python/../../../../libtensorflow_framework.2.dylib' (no such file), '/Users/cyanaspect/opt/anaconda3/envs/ml/lib/python3.7/site-packages/tensorflow_core/python/../../_solib_darwin/_U_S_Stensorflow_Spython_C_Upywrap_Utensorflow_Uinternal.so___Utensorflow/libtensorflow_framework.2.dylib' (no such file), '/Users/cyanaspect/opt/anaconda3/envs/ml/lib/python3.7/site-packages/tensorflow_core/python/../../_solib_darwin/_U@mkl_Udarwin_S_S_Cmkl_Ulibs_Udarwin___Uexternal_Smkl_Udarwin_Slib/libtensorflow_framework.2.dylib' (no such file), '/Users/cyanaspect/opt/anaconda3/envs/ml/lib/python3.7/site-packages/tensorflow_core/python/libtensorflow_framework.2.dylib' (no such file), '/Users/cyanaspect/opt/anaconda3/envs/ml/lib/python3.7/site-packages/tensorflow_core/python/../libtensorflow_framework.2.dylib' (no such file), '/Users/cyanaspect/opt/anaconda3/envs/ml/lib/python3.7/site-packages/tensorflow_core/python/../../../../libtensorflow_framework.2.dylib' (no such file), '/Users/cyanaspect/opt/anaconda3/envs/ml/bin/../lib/libtensorflow_framework.2.dylib' (no such file), '/Users/cyanaspect/opt/anaconda3/envs/ml/bin/../lib/libtensorflow_framework.2.dylib' (no such file), '/usr/local/lib/libtensorflow_framework.2.dylib' (no such file), '/usr/lib/libtensorflow_framework.2.dylib' (no such file)\n",
      "\n",
      "\n",
      "Failed to load the native TensorFlow runtime.\n",
      "\n",
      "See https://www.tensorflow.org/install/errors\n",
      "\n",
      "for some common reasons and solutions.  Include the entire stack trace\n",
      "above this error message when asking for help.\n"
     ]
    }
   ],
   "source": [
    "display_series(clusters[5].title)"
   ]
  },
  {
   "cell_type": "markdown",
   "id": "a0291a78",
   "metadata": {},
   "source": [
    "# Parsing into events"
   ]
  },
  {
   "cell_type": "code",
   "execution_count": 258,
   "id": "690fe29b",
   "metadata": {},
   "outputs": [
    {
     "name": "stdout",
     "output_type": "stream",
     "text": [
      "ERROR! Session/line number was not unique in database. History logging moved to new session 264\n"
     ]
    }
   ],
   "source": [
    "import copy\n",
    "\n",
    "def remove_largest_cluster_of_each_window(clusters_for_each_window):\n",
    "    '''\n",
    "    Given a list of list of DataFrames, where clusters_for_each_window[w][c]\n",
    "    is the DataFrame corresponding to the c-th cluster for the w-th window,\n",
    "    remove the largest cluster from each window.\n",
    "    '''\n",
    "    # Have to define custom helper function because remove(max(...)) raises\n",
    "    # ValueError: Can only compare df with same index\n",
    "    def remove_largest_df_in_list(dfs):\n",
    "        largest_df_idx = 0\n",
    "        for i in range(len(dfs)):\n",
    "            if len(dfs[i]) > len(dfs[largest_df_idx]):\n",
    "                largest_df_idx = i\n",
    "        del dfs[largest_df_idx]\n",
    "        \n",
    "    clusters_for_each_window = copy.deepcopy(clusters_for_each_window)\n",
    "    for clusters_for_window in clusters_for_each_window:\n",
    "        remove_largest_df_in_list(clusters_for_window)\n",
    "    return clusters_for_each_window\n",
    "\n",
    "clusters_for_each_window = remove_largest_cluster_of_each_window(clusters_for_each_window)"
   ]
  },
  {
   "cell_type": "code",
   "execution_count": 259,
   "id": "235a79e4",
   "metadata": {
    "scrolled": false
   },
   "outputs": [],
   "source": [
    "from sklearn.metrics import pairwise_distances_argmin_min\n",
    "\n",
    "def get_event_title(event):\n",
    "    '''\n",
    "    Given an event (a DataFrame of articles),\n",
    "    Returns the title of that event.\n",
    "    '''\n",
    "    embeddings = [embedding for embedding in event.embeddings]\n",
    "    mean_embedding = np.array([np.mean(embeddings, axis=0)])\n",
    "    index = pairwise_distances_argmin_min(mean_embedding, embeddings)[0][0]\n",
    "    return event.title.iloc[index]\n",
    "\n",
    "def get_modal_date(event):\n",
    "    '''\n",
    "    Given an event (a DataFrame of articles),\n",
    "    Returns the modal date of articles in that event.\n",
    "    '''\n",
    "    dates = event.published_time.dt.date\n",
    "    return dates.mode()[0]\n",
    "\n",
    "def to_article_dicts(event):\n",
    "    '''\n",
    "    Given a DataFrame representing a cluster of articles, \n",
    "    Returns a list of dictionaries, where each dictionary is an article.\n",
    "    '''\n",
    "    event = event.drop(columns=['content', 'embeddings']) \n",
    "    return event.to_dict('records')\n",
    "\n",
    "def parse_into_events(clusters_for_each_window):\n",
    "    '''\n",
    "    Given a list of list of DataFrames, where clusters_for_each_window[w][c]\n",
    "    is the DataFrame corresponding to the c-th cluster for the w-th window,\n",
    "    Returns a list of events sorted by date, where each event is a dictionary:\n",
    "    {\n",
    "        'name': string\n",
    "        'date': date\n",
    "        'articles': [\n",
    "            {\n",
    "                'title': string\n",
    "                'published_time': date\n",
    "                'url': string\n",
    "                'thumbnail_url': string\n",
    "            }, \n",
    "        ]\n",
    "    }\n",
    "    '''\n",
    "    events = []\n",
    "    for window in clusters_for_each_window:\n",
    "        for cluster in window:\n",
    "            event = {\n",
    "                'name': get_event_title(cluster),\n",
    "                'date': get_modal_date(cluster).isoformat(), \n",
    "                'articles': to_article_dicts(cluster)\n",
    "            }\n",
    "            events.append(event)\n",
    "    return sorted(events, key=lambda event : event['date'], reverse=True)\n",
    "\n",
    "\n",
    "events = parse_into_events(clusters_for_each_window)"
   ]
  },
  {
   "cell_type": "code",
   "execution_count": 262,
   "id": "f4184ef3",
   "metadata": {},
   "outputs": [
    {
     "data": {
      "text/plain": [
       "{'name': 'Nearly-man Moriyasu remains in charge of Japan for another four-year cycle',\n",
       " 'date': '2022-12-28',\n",
       " 'articles': [{'title': \"Japan's World Cup coach Moriyasu to stay until 2026\",\n",
       "   'description': \"The coach of Japan's national soccer team, Hajime Moriyasu, who led the Samurai Blue to the knock-out stage of the Qatar World Cup, will stay on to lead the team into the next World Cup in 2026, the Japan Football Association said on Wednesday.\",\n",
       "   'uuid': '263775ad-ade9-49fb-b552-9a68007c1d77',\n",
       "   'thumbnail_url': 'https://www.reuters.com/resizer/6-aq20NIlpe7zu_diPjsZRC9ybI=/1200x628/smart/filters:quality(80)/cloudfront-us-east-2.images.arcpublishing.com/reuters/JCRFMFRN6BORNPXOGCOV3VFE74.jpg',\n",
       "   'url': 'https://www.reuters.com/lifestyle/sports/japans-world-cup-coach-moriyasu-stay-until-2026-2022-12-28/',\n",
       "   'published_time': Timestamp('2022-12-28 10:26:14'),\n",
       "   'source': 'reuters.com'},\n",
       "  {'title': 'Nearly-man Moriyasu remains in charge of Japan for another four-year cycle',\n",
       "   'description': \"Japan coach Hajime Moriyasu will remain in charge of the Asian team for another World Cup cycle, the country's football association announced on Thursday, with the aim of breaking new ground after a number of near misses.\",\n",
       "   'uuid': 'b877cbfa-c34a-4704-8361-db7c51c5d2d8',\n",
       "   'thumbnail_url': 'https://www.reuters.com/resizer/EQ9epbVPnZ7jn4zRRexTGopTEiQ=/1200x628/smart/filters:quality(80)/cloudfront-us-east-2.images.arcpublishing.com/reuters/A6NMB33KDJNH7KWQ3O5UUZ4M7Y.jpg',\n",
       "   'url': 'https://www.reuters.com/lifestyle/sports/nearly-man-moriyasu-remains-charge-japan-another-four-year-cycle-2022-12-29/',\n",
       "   'published_time': Timestamp('2022-12-29 14:57:36'),\n",
       "   'source': 'reuters.com'},\n",
       "  {'title': \"Arsenal's Tomiyasu available after World Cup, Smith Rowe close to return\",\n",
       "   'description': \"Japan's Takehiro Tomiyasu will be available for leaders Arsenal at Brighton & Hove Albion in the Premier League on Saturday after returning from the World Cup, manager Mikel Arteta said.\",\n",
       "   'uuid': '24def6d6-77f8-40bb-b40b-8adcf1a030fb',\n",
       "   'thumbnail_url': 'https://www.reuters.com/resizer/WcpmOJ4WJxiYWqVZ1c_D5pOkTvY=/1200x628/smart/filters:quality(80)/cloudfront-us-east-2.images.arcpublishing.com/reuters/JG2JMPQKX5OYNEQFQMEHMKHQ3E.jpg',\n",
       "   'url': 'https://www.reuters.com/lifestyle/sports/arsenals-tomiyasu-available-after-world-cup-smith-rowe-close-return-2022-12-30/',\n",
       "   'published_time': Timestamp('2022-12-30 18:01:23'),\n",
       "   'source': 'reuters.com'}]}"
      ]
     },
     "execution_count": 262,
     "metadata": {},
     "output_type": "execute_result"
    }
   ],
   "source": [
    "events[2]"
   ]
  },
  {
   "cell_type": "code",
   "execution_count": null,
   "id": "8710778b",
   "metadata": {},
   "outputs": [],
   "source": []
  },
  {
   "cell_type": "code",
   "execution_count": null,
   "id": "62a8161c",
   "metadata": {},
   "outputs": [],
   "source": []
  },
  {
   "cell_type": "code",
   "execution_count": null,
   "id": "8ea9c035",
   "metadata": {},
   "outputs": [],
   "source": []
  },
  {
   "cell_type": "code",
   "execution_count": null,
   "id": "95697ad4",
   "metadata": {},
   "outputs": [],
   "source": []
  }
 ],
 "metadata": {
  "kernelspec": {
   "display_name": "Python 3 (ipykernel)",
   "language": "python",
   "name": "python3"
  },
  "language_info": {
   "codemirror_mode": {
    "name": "ipython",
    "version": 3
   },
   "file_extension": ".py",
   "mimetype": "text/x-python",
   "name": "python",
   "nbconvert_exporter": "python",
   "pygments_lexer": "ipython3",
   "version": "3.7.15"
  }
 },
 "nbformat": 4,
 "nbformat_minor": 5
}
